[32mINFO    [0m pytest_operator.plugin:plugin.py:734 Connecting to existing model concierge-lxd:testing on unspecified cloud
[32mINFO    [0m integration.test_exporter:test_exporter.py:32 Deploying all the applications
[32mINFO    [0m juju.model:model.py:2284 Deploying ch:amd64/jammy/mysql-test-app-69
[32mINFO    [0m juju.model:model.py:2284 Deploying ch:amd64/jammy/grafana-agent-365
[32mINFO    [0m juju.model:model.py:2284 Deploying ch:amd64/jammy/mysql-349
[32mINFO    [0m juju.model:model.py:2284 Deploying local:jammy/mysql-router-0
[32mINFO    [0m integration.test_exporter:test_exporter.py:70 Relating mysqlrouter and grafana-agent with mysql-test-app
[33mWARNING [0m juju.model:model.py:1666 relate is deprecated and will be removed. Use integrate instead.
[33mWARNING [0m juju.model:model.py:1666 relate is deprecated and will be removed. Use integrate instead.
[32mINFO    [0m integration.test_exporter:test_exporter.py:94 Relating mysqlrouter with mysql
[33mWARNING [0m juju.model:model.py:1666 relate is deprecated and will be removed. Use integrate instead.
[32mINFO    [0m integration.test_exporter:test_exporter.py:123 Relating mysqlrouter with grafana agent
[33mWARNING [0m juju.model:model.py:1666 relate is deprecated and will be removed. Use integrate instead.
[32mINFO    [0m integration.test_exporter:test_exporter.py:141 Removing relation between mysqlrouter and grafana agent
[32mINFO    [0m pytest_operator.plugin:plugin.py:862 Model status:

Model    Controller     Cloud/Region         Version  SLA          Timestamp
testing  concierge-lxd  localhost/localhost  3.6.2    unsupported  01:34:35Z

App             Version          Status   Scale  Charm           Channel        Rev  Exposed  Message
grafana-agent                    blocked      1  grafana-agent   latest/stable  365  no       Missing ['grafana-cloud-config']|['logging-consumer']|['send-remote-write'] for juju-info
mysql           8.0.41-0ubun...  active       1  mysql           8.0/edge       349  no       
mysql-router    8.0.41-0ubun...  active       1  mysql-router                     0  no       
mysql-test-app  0.0.2            active       1  mysql-test-app  latest/edge     69  no       

Unit                Workload  Agent      Machine  Public address  Ports           Message
mysql-test-app/0*   active    idle       0        10.32.187.43                    
  grafana-agent/0*  blocked   idle                10.32.187.43                    Missing ['grafana-cloud-config']|['logging-consumer']|['send-remote-write'] for juju-info
  mysql-router/0*   active    executing           10.32.187.43                    
mysql/0*            active    idle       1        10.32.187.66    3306,33060/tcp  Primary

Machine  State    Address       Inst id        Base          AZ  Message
0        started  10.32.187.43  juju-a3cfd5-0  ubuntu@22.04      Running
1        started  10.32.187.66  juju-a3cfd5-1  ubuntu@22.04      Running

[32mINFO    [0m pytest_operator.plugin:plugin.py:868 Juju error logs:

machine-0: 01:31:59 ERROR juju.worker.dependency "lxd-container-provisioner" manifold worker returned unexpected error: container types not yet available
machine-0: 01:31:59 ERROR juju.worker.dependency "kvm-container-provisioner" manifold worker returned unexpected error: container types not yet available
unit-mysql-test-app-0: 01:31:59 ERROR juju.worker.meterstatus error running "meter-status-changed": charm missing from disk
unit-grafana-agent-0: 01:32:02 ERROR juju.worker.meterstatus error running "meter-status-changed": exit status 127
unit-mysql-router-0: 01:32:02 ERROR juju.worker.meterstatus error running "meter-status-changed": exit status 1
machine-1: 01:33:05 ERROR juju.worker.dependency "lxd-container-provisioner" manifold worker returned unexpected error: container types not yet available
machine-1: 01:33:05 ERROR juju.worker.dependency "kvm-container-provisioner" manifold worker returned unexpected error: container types not yet available
unit-mysql-0: 01:33:05 ERROR juju.worker.meterstatus error running "meter-status-changed": charm missing from disk
unit-mysql-router-0: 01:34:28 ERROR unit.mysql-router/0.juju-log cos-agent:12: Exception while exporting Span batch.
Traceback (most recent call last):
  File "/var/lib/juju/agents/unit-mysql-router-0/charm/venv/lib/python3.10/site-packages/urllib3/connection.py", line 196, in _new_conn
    sock = connection.create_connection(
  File "/var/lib/juju/agents/unit-mysql-router-0/charm/venv/lib/python3.10/site-packages/urllib3/util/connection.py", line 85, in create_connection
    raise err
  File "/var/lib/juju/agents/unit-mysql-router-0/charm/venv/lib/python3.10/site-packages/urllib3/util/connection.py", line 73, in create_connection
    sock.connect(sa)
ConnectionRefusedError: [Errno 111] Connection refused

The above exception was the direct cause of the following exception:

Traceback (most recent call last):
  File "/var/lib/juju/agents/unit-mysql-router-0/charm/venv/lib/python3.10/site-packages/urllib3/connectionpool.py", line 789, in urlopen
    response = self._make_request(
  File "/var/lib/juju/agents/unit-mysql-router-0/charm/venv/lib/python3.10/site-packages/urllib3/connectionpool.py", line 495, in _make_request
    conn.request(
  File "/var/lib/juju/agents/unit-mysql-router-0/charm/venv/lib/python3.10/site-packages/urllib3/connection.py", line 398, in request
    self.endheaders()
  File "/usr/lib/python3.10/http/client.py", line 1278, in endheaders
    self._send_output(message_body, encode_chunked=encode_chunked)
  File "/usr/lib/python3.10/http/client.py", line 1038, in _send_output
    self.send(msg)
  File "/usr/lib/python3.10/http/client.py", line 976, in send
    self.connect()
  File "/var/lib/juju/agents/unit-mysql-router-0/charm/venv/lib/python3.10/site-packages/urllib3/connection.py", line 236, in connect
    self.sock = self._new_conn()
  File "/var/lib/juju/agents/unit-mysql-router-0/charm/venv/lib/python3.10/site-packages/urllib3/connection.py", line 211, in _new_conn
    raise NewConnectionError(
urllib3.exceptions.NewConnectionError: <urllib3.connection.HTTPConnection object at 0x7f86920daaa0>: Failed to establish a new connection: [Errno 111] Connection refused

The above exception was the direct cause of the following exception:

Traceback (most recent call last):
  File "/var/lib/juju/agents/unit-mysql-router-0/charm/venv/lib/python3.10/site-packages/requests/adapters.py", line 667, in send
    resp = conn.urlopen(
  File "/var/lib/juju/agents/unit-mysql-router-0/charm/venv/lib/python3.10/site-packages/urllib3/connectionpool.py", line 843, in urlopen
    retries = retries.increment(
  File "/var/lib/juju/agents/unit-mysql-router-0/charm/venv/lib/python3.10/site-packages/urllib3/util/retry.py", line 519, in increment
    raise MaxRetryError(_pool, url, reason) from reason  # type: ignore[arg-type]
urllib3.exceptions.MaxRetryError: HTTPConnectionPool(host='juju-a3cfd5-0.lxd', port=4318): Max retries exceeded with url: /v1/traces (Caused by NewConnectionError('<urllib3.connection.HTTPConnection object at 0x7f86920daaa0>: Failed to establish a new connection: [Errno 111] Connection refused'))

During handling of the above exception, another exception occurred:

Traceback (most recent call last):
  File "/var/lib/juju/agents/unit-mysql-router-0/charm/venv/lib/python3.10/site-packages/opentelemetry/sdk/trace/export/__init__.py", line 368, in _export_batch
    self.span_exporter.export(self.spans_list[:idx])  # type: ignore
  File "/var/lib/juju/agents/unit-mysql-router-0/charm/venv/lib/python3.10/site-packages/opentelemetry/exporter/otlp/proto/http/trace_exporter/__init__.py", line 145, in export
    resp = self._export(serialized_data)
  File "/var/lib/juju/agents/unit-mysql-router-0/charm/venv/lib/python3.10/site-packages/opentelemetry/exporter/otlp/proto/http/trace_exporter/__init__.py", line 114, in _export
    return self._session.post(
  File "/var/lib/juju/agents/unit-mysql-router-0/charm/venv/lib/python3.10/site-packages/requests/sessions.py", line 637, in post
    return self.request("POST", url, data=data, json=json, **kwargs)
  File "/var/lib/juju/agents/unit-mysql-router-0/charm/venv/lib/python3.10/site-packages/requests/sessions.py", line 589, in request
    resp = self.send(prep, **send_kwargs)
  File "/var/lib/juju/agents/unit-mysql-router-0/charm/venv/lib/python3.10/site-packages/requests/sessions.py", line 703, in send
    r = adapter.send(request, **kwargs)
  File "/var/lib/juju/agents/unit-mysql-router-0/charm/venv/lib/python3.10/site-packages/requests/adapters.py", line 700, in send
    raise ConnectionError(e, request=request)
requests.exceptions.ConnectionError: HTTPConnectionPool(host='juju-a3cfd5-0.lxd', port=4318): Max retries exceeded with url: /v1/traces (Caused by NewConnectionError('<urllib3.connection.HTTPConnection object at 0x7f86920daaa0>: Failed to establish a new connection: [Errno 111] Connection refused'))

[32mINFO    [0m pytest_operator.plugin:plugin.py:947 Forgetting model main...