[32mINFO    [0m pytest_operator.plugin:plugin.py:862 Model status:

Model    Controller     Cloud/Region         Version  SLA          Timestamp
testing  concierge-lxd  localhost/localhost  3.6.7    unsupported  01:59:00Z

App              Version          Status  Scale  Charm            Channel        Rev  Exposed  Message
data-integrator                   active      4  data-integrator  latest/stable   78  no       
hacluster        2.1.2            active      4  hacluster        2.4/stable     131  no       Unit is ready and clustered
mysql            8.0.41-0ubun...  active      1  mysql            8.0/edge       378  no       
mysql-router     8.0.41-0ubun...  active      4  mysql-router                      0  no       

Unit                Workload  Agent      Machine  Public address  Ports           Message
data-integrator/0*  active    idle       0        10.143.167.253                  
  hacluster/4       active    idle                10.143.167.253                  Unit is ready and clustered
  mysql-router/0*   active    idle                10.143.167.253  6446-6447/tcp   
data-integrator/1   active    executing  1        10.143.167.185                  (start) 
  hacluster/0*      active    executing           10.143.167.185                  (start) Unit is ready and clustered
  mysql-router/2    error     idle                10.143.167.185  6446-6447/tcp   hook failed: "update-status"
data-integrator/2   active    idle       2        10.143.167.171                  
  hacluster/5       active    idle                10.143.167.171                  Unit is ready and clustered
  mysql-router/1    active    idle                10.143.167.171  6446-6447/tcp   
data-integrator/3   active    idle       3        10.143.167.58                   
  hacluster/3       active    idle                10.143.167.58                   Unit is ready and clustered
  mysql-router/3    active    idle                10.143.167.58   6446-6447/tcp   
mysql/0*            active    idle       4        10.143.167.189  3306,33060/tcp  Primary

Machine  State    Address         Inst id        Base          AZ  Message
0        started  10.143.167.253  juju-517459-0  ubuntu@22.04      Running
1        started  10.143.167.185  juju-517459-1  ubuntu@22.04      Running
2        started  10.143.167.171  juju-517459-2  ubuntu@22.04      Running
3        started  10.143.167.58   juju-517459-3  ubuntu@22.04      Running
4        started  10.143.167.189  juju-517459-4  ubuntu@22.04      Running

[32mINFO    [0m pytest_operator.plugin:plugin.py:868 Juju error logs:

machine-0: 01:45:20 ERROR juju.worker.dependency "kvm-container-provisioner" manifold worker returned unexpected error: container types not yet available
machine-0: 01:45:20 ERROR juju.worker.dependency "lxd-container-provisioner" manifold worker returned unexpected error: container types not yet available
unit-data-integrator-0: 01:45:20 ERROR juju.worker.meterstatus error running "meter-status-changed": charm missing from disk
unit-mysql-router-0: 01:45:23 ERROR juju.worker.meterstatus error running "meter-status-changed": exit status 1
machine-2: 01:47:22 ERROR juju.worker.dependency "lxd-container-provisioner" manifold worker returned unexpected error: container types not yet available
machine-2: 01:47:22 ERROR juju.worker.dependency "kvm-container-provisioner" manifold worker returned unexpected error: container types not yet available
unit-data-integrator-2: 01:47:22 ERROR juju.worker.meterstatus error running "meter-status-changed": charm missing from disk
unit-mysql-router-1: 01:47:29 ERROR juju.worker.meterstatus error running "meter-status-changed": charm missing from disk
machine-4: 01:47:41 ERROR juju.worker.dependency "lxd-container-provisioner" manifold worker returned unexpected error: container types not yet available
machine-4: 01:47:41 ERROR juju.worker.dependency "kvm-container-provisioner" manifold worker returned unexpected error: container types not yet available
unit-mysql-0: 01:47:41 ERROR juju.worker.meterstatus error running "meter-status-changed": charm missing from disk
machine-1: 01:48:04 ERROR juju.worker.dependency "lxd-container-provisioner" manifold worker returned unexpected error: container types not yet available
machine-1: 01:48:04 ERROR juju.worker.dependency "kvm-container-provisioner" manifold worker returned unexpected error: container types not yet available
unit-data-integrator-1: 01:48:05 ERROR juju.worker.meterstatus error running "meter-status-changed": charm missing from disk
unit-mysql-router-2: 01:48:11 ERROR juju.worker.meterstatus error running "meter-status-changed": charm missing from disk
machine-3: 01:48:25 ERROR juju.worker.dependency "lxd-container-provisioner" manifold worker returned unexpected error: container types not yet available
machine-3: 01:48:25 ERROR juju.worker.dependency "kvm-container-provisioner" manifold worker returned unexpected error: container types not yet available
unit-data-integrator-3: 01:48:25 ERROR juju.worker.meterstatus error running "meter-status-changed": charm missing from disk
unit-mysql-router-3: 01:48:32 ERROR juju.worker.meterstatus error running "meter-status-changed": exit status 1
unit-mysql-router-1: 01:49:37 ERROR unit.mysql-router/1.juju-log backend-database:8: Failed to run MySQL Shell script:
import json
import mysqlsh
import traceback

try:
    # Disable wizards in this script, since it will be invoked without --no-wizard
    shell.options.set('useWizards', False)
    import json

    result = session.run_sql(
        "SELECT USER, ATTRIBUTE->>'$.router_id' FROM INFORMATION_SCHEMA.USER_ATTRIBUTES WHERE ATTRIBUTE->'$.created_by_user'='relation-8_7ae48bc246f54a6' AND ATTRIBUTE->'$.created_by_juju_unit'='mysql-router/1'"
    )
    rows = result.fetch_all()
    # mysqlsh objects are weirdâ€”they quack (i.e. duck typing) like standard Python objects (e.g. list,
    # dict), but do not serialize to JSON correctly.
    # Cast to str & load from JSON str before serializing
    rows = json.loads(str(rows))
    with open("/tmp/mysqlsh_output.json", "w") as file:
        json.dump(rows, file)
except mysqlsh.DBError as exception:
    error = {
        "message": str(exception),
        "code": exception.code,
        "traceback_message": "".join(traceback.format_exception(exception)),
    }
else:
    error = None
with open("/tmp/mysqlsh_error.json", "w") as file:
    json.dump(error, file)

stderr:
[31mERROR: [0mFailed to retrieve the password: Process "mysql_config_editor" finished with exit code 1: mysql_config_editor: Can't create/write to file '/root/snap/charmed-mysql/139/.mylogin.cnf' (OS errno 13 - Permission denied)
couldn't create the login file : Permission denied
mysql_config_editor: Error on close of '<fd out of range>' (OS errno 9 - Bad file descriptor)
operation failed. : Bad file descriptor
MySQL Error 2005: No such host is known ''

Traceback (most recent call last):
  File "/var/lib/juju/agents/unit-mysql-router-1/charm/src/snap.py", line 263, in _run_command
    output = subprocess.run(
  File "/usr/lib/python3.10/subprocess.py", line 526, in run
    raise CalledProcessError(retcode, process.args,
subprocess.CalledProcessError: Command '['charmed-mysql.mysqlsh', '--passwords-from-stdin', '--uri', 'relation-8_7ae48bc246f54a6@:3306', '--python', '--file', '/tmp/mysqlsh_script.py']' returned non-zero exit status 1.

During handling of the above exception, another exception occurred:

Traceback (most recent call last):
  File "/var/lib/juju/agents/unit-mysql-router-1/charm/src/mysql_shell/__init__.py", line 74, in _run_code
    self._container.run_mysql_shell(
  File "/var/lib/juju/agents/unit-mysql-router-1/charm/lib/charms/tempo_coordinator_k8s/v0/charm_tracing.py", line 738, in wrapped_function
    return callable(*args, **kwargs)  # type: ignore
  File "/var/lib/juju/agents/unit-mysql-router-1/charm/src/container.py", line 212, in run_mysql_shell
    return self._run_command(args, timeout=timeout, input=input)
  File "/var/lib/juju/agents/unit-mysql-router-1/charm/lib/charms/tempo_coordinator_k8s/v0/charm_tracing.py", line 738, in wrapped_function
    return callable(*args, **kwargs)  # type: ignore
  File "/var/lib/juju/agents/unit-mysql-router-1/charm/src/snap.py", line 272, in _run_command
    raise container.CalledProcessError(
container.CalledProcessError: Command '['charmed-mysql.mysqlsh', '--passwords-from-stdin', '--uri', 'relation-8_7ae48bc246f54a6@:3306', '--python', '--file', '/tmp/mysqlsh_script.py']' returned non-zero exit status 1.
unit-mysql-router-1: 01:49:37 ERROR unit.mysql-router/1.juju-log backend-database:8: Uncaught exception while in charm code:
Traceback (most recent call last):
  File "/var/lib/juju/agents/unit-mysql-router-1/charm/src/snap.py", line 263, in _run_command
    output = subprocess.run(
  File "/usr/lib/python3.10/subprocess.py", line 526, in run
    raise CalledProcessError(retcode, process.args,
subprocess.CalledProcessError: Command '['charmed-mysql.mysqlsh', '--passwords-from-stdin', '--uri', 'relation-8_7ae48bc246f54a6@:3306', '--python', '--file', '/tmp/mysqlsh_script.py']' returned non-zero exit status 1.

During handling of the above exception, another exception occurred:

Traceback (most recent call last):
  File "/var/lib/juju/agents/unit-mysql-router-1/charm/src/charm.py", line 235, in <module>
    ops.main.main(MachineSubordinateRouterCharm)
  File "/var/lib/juju/agents/unit-mysql-router-1/charm/venv/lib/python3.10/site-packages/ops/main.py", line 436, in main
    _emit_charm_event(charm, dispatcher.event_name)
  File "/var/lib/juju/agents/unit-mysql-router-1/charm/venv/lib/python3.10/site-packages/ops/main.py", line 144, in _emit_charm_event
    event_to_emit.emit(*args, **kwargs)
  File "/var/lib/juju/agents/unit-mysql-router-1/charm/venv/lib/python3.10/site-packages/ops/framework.py", line 351, in emit
    framework._emit(event)
  File "/var/lib/juju/agents/unit-mysql-router-1/charm/venv/lib/python3.10/site-packages/ops/framework.py", line 853, in _emit
    self._reemit(event_path)
  File "/var/lib/juju/agents/unit-mysql-router-1/charm/venv/lib/python3.10/site-packages/ops/framework.py", line 942, in _reemit
    custom_handler(event)
  File "/var/lib/juju/agents/unit-mysql-router-1/charm/lib/charms/data_platform_libs/v0/data_interfaces.py", line 3141, in _on_relation_changed_event
    getattr(self.on, "database_created").emit(
  File "/var/lib/juju/agents/unit-mysql-router-1/charm/venv/lib/python3.10/site-packages/ops/framework.py", line 351, in emit
    framework._emit(event)
  File "/var/lib/juju/agents/unit-mysql-router-1/charm/venv/lib/python3.10/site-packages/ops/framework.py", line 853, in _emit
    self._reemit(event_path)
  File "/var/lib/juju/agents/unit-mysql-router-1/charm/venv/lib/python3.10/site-packages/ops/framework.py", line 942, in _reemit
    custom_handler(event)
  File "/var/lib/juju/agents/unit-mysql-router-1/charm/lib/charms/tempo_coordinator_k8s/v0/charm_tracing.py", line 738, in wrapped_function
    return callable(*args, **kwargs)  # type: ignore
  File "/var/lib/juju/agents/unit-mysql-router-1/charm/src/abstract_charm.py", line 355, in reconcile
    workload_.reconcile(
  File "/var/lib/juju/agents/unit-mysql-router-1/charm/lib/charms/tempo_coordinator_k8s/v0/charm_tracing.py", line 738, in wrapped_function
    return callable(*args, **kwargs)  # type: ignore
  File "/var/lib/juju/agents/unit-mysql-router-1/charm/src/workload.py", line 399, in reconcile
    self._enable_router(event=event, tls=tls, unit_name=unit_name)
  File "/var/lib/juju/agents/unit-mysql-router-1/charm/lib/charms/tempo_coordinator_k8s/v0/charm_tracing.py", line 738, in wrapped_function
    return callable(*args, **kwargs)  # type: ignore
  File "/var/lib/juju/agents/unit-mysql-router-1/charm/src/workload.py", line 331, in _enable_router
    self._cleanup_after_upgrade_or_potential_container_restart()
  File "/var/lib/juju/agents/unit-mysql-router-1/charm/lib/charms/tempo_coordinator_k8s/v0/charm_tracing.py", line 738, in wrapped_function
    return callable(*args, **kwargs)  # type: ignore
  File "/var/lib/juju/agents/unit-mysql-router-1/charm/src/workload.py", line 228, in _cleanup_after_upgrade_or_potential_container_restart
    if user_info := self.shell.get_mysql_router_user_for_unit(self._charm.unit.name):
  File "/var/lib/juju/agents/unit-mysql-router-1/charm/src/mysql_shell/__init__.py", line 167, in get_mysql_router_user_for_unit
    self._run_code(
  File "/var/lib/juju/agents/unit-mysql-router-1/charm/src/mysql_shell/__init__.py", line 74, in _run_code
    self._container.run_mysql_shell(
  File "/var/lib/juju/agents/unit-mysql-router-1/charm/lib/charms/tempo_coordinator_k8s/v0/charm_tracing.py", line 738, in wrapped_function
    return callable(*args, **kwargs)  # type: ignore
  File "/var/lib/juju/agents/unit-mysql-router-1/charm/src/container.py", line 212, in run_mysql_shell
    return self._run_command(args, timeout=timeout, input=input)
  File "/var/lib/juju/agents/unit-mysql-router-1/charm/lib/charms/tempo_coordinator_k8s/v0/charm_tracing.py", line 738, in wrapped_function
    return callable(*args, **kwargs)  # type: ignore
  File "/var/lib/juju/agents/unit-mysql-router-1/charm/src/snap.py", line 272, in _run_command
    raise container.CalledProcessError(
container.CalledProcessError: Command '['charmed-mysql.mysqlsh', '--passwords-from-stdin', '--uri', 'relation-8_7ae48bc246f54a6@:3306', '--python', '--file', '/tmp/mysqlsh_script.py']' returned non-zero exit status 1.
unit-mysql-router-2: 01:49:37 ERROR unit.mysql-router/2.juju-log backend-database:8: Failed to run MySQL Shell script:
import json
import mysqlsh
import traceback

try:
    # Disable wizards in this script, since it will be invoked without --no-wizard
    shell.options.set('useWizards', False)
    import json

    result = session.run_sql(
        "SELECT USER, ATTRIBUTE->>'$.router_id' FROM INFORMATION_SCHEMA.USER_ATTRIBUTES WHERE ATTRIBUTE->'$.created_by_user'='relation-8_7ae48bc246f54a6' AND ATTRIBUTE->'$.created_by_juju_unit'='mysql-router/2'"
    )
    rows = result.fetch_all()
    # mysqlsh objects are weirdâ€”they quack (i.e. duck typing) like standard Python objects (e.g. list,
    # dict), but do not serialize to JSON correctly.
    # Cast to str & load from JSON str before serializing
    rows = json.loads(str(rows))
    with open("/tmp/mysqlsh_output.json", "w") as file:
        json.dump(rows, file)
except mysqlsh.DBError as exception:
    error = {
        "message": str(exception),
        "code": exception.code,
        "traceback_message": "".join(traceback.format_exception(exception)),
    }
else:
    error = None
with open("/tmp/mysqlsh_error.json", "w") as file:
    json.dump(error, file)

stderr:
[31mERROR: [0mFailed to retrieve the password: Process "mysql_config_editor" finished with exit code 1: mysql_config_editor: Can't create/write to file '/root/snap/charmed-mysql/139/.mylogin.cnf' (OS errno 13 - Permission denied)
couldn't create the login file : Permission denied
mysql_config_editor: Error on close of '<fd out of range>' (OS errno 9 - Bad file descriptor)
operation failed. : Bad file descriptor
MySQL Error 2005: No such host is known ''

Traceback (most recent call last):
  File "/var/lib/juju/agents/unit-mysql-router-2/charm/src/snap.py", line 263, in _run_command
    output = subprocess.run(
  File "/usr/lib/python3.10/subprocess.py", line 526, in run
    raise CalledProcessError(retcode, process.args,
subprocess.CalledProcessError: Command '['charmed-mysql.mysqlsh', '--passwords-from-stdin', '--uri', 'relation-8_7ae48bc246f54a6@:3306', '--python', '--file', '/tmp/mysqlsh_script.py']' returned non-zero exit status 1.

During handling of the above exception, another exception occurred:

Traceback (most recent call last):
  File "/var/lib/juju/agents/unit-mysql-router-2/charm/src/mysql_shell/__init__.py", line 74, in _run_code
    self._container.run_mysql_shell(
  File "/var/lib/juju/agents/unit-mysql-router-2/charm/lib/charms/tempo_coordinator_k8s/v0/charm_tracing.py", line 738, in wrapped_function
    return callable(*args, **kwargs)  # type: ignore
  File "/var/lib/juju/agents/unit-mysql-router-2/charm/src/container.py", line 212, in run_mysql_shell
    return self._run_command(args, timeout=timeout, input=input)
  File "/var/lib/juju/agents/unit-mysql-router-2/charm/lib/charms/tempo_coordinator_k8s/v0/charm_tracing.py", line 738, in wrapped_function
    return callable(*args, **kwargs)  # type: ignore
  File "/var/lib/juju/agents/unit-mysql-router-2/charm/src/snap.py", line 272, in _run_command
    raise container.CalledProcessError(
container.CalledProcessError: Command '['charmed-mysql.mysqlsh', '--passwords-from-stdin', '--uri', 'relation-8_7ae48bc246f54a6@:3306', '--python', '--file', '/tmp/mysqlsh_script.py']' returned non-zero exit status 1.
unit-mysql-router-2: 01:49:37 ERROR unit.mysql-router/2.juju-log backend-database:8: Uncaught exception while in charm code:
Traceback (most recent call last):
  File "/var/lib/juju/agents/unit-mysql-router-2/charm/src/snap.py", line 263, in _run_command
    output = subprocess.run(
  File "/usr/lib/python3.10/subprocess.py", line 526, in run
    raise CalledProcessError(retcode, process.args,
subprocess.CalledProcessError: Command '['charmed-mysql.mysqlsh', '--passwords-from-stdin', '--uri', 'relation-8_7ae48bc246f54a6@:3306', '--python', '--file', '/tmp/mysqlsh_script.py']' returned non-zero exit status 1.

During handling of the above exception, another exception occurred:

Traceback (most recent call last):
  File "/var/lib/juju/agents/unit-mysql-router-2/charm/src/charm.py", line 235, in <module>
    ops.main.main(MachineSubordinateRouterCharm)
  File "/var/lib/juju/agents/unit-mysql-router-2/charm/venv/lib/python3.10/site-packages/ops/main.py", line 436, in main
    _emit_charm_event(charm, dispatcher.event_name)
  File "/var/lib/juju/agents/unit-mysql-router-2/charm/venv/lib/python3.10/site-packages/ops/main.py", line 144, in _emit_charm_event
    event_to_emit.emit(*args, **kwargs)
  File "/var/lib/juju/agents/unit-mysql-router-2/charm/venv/lib/python3.10/site-packages/ops/framework.py", line 351, in emit
    framework._emit(event)
  File "/var/lib/juju/agents/unit-mysql-router-2/charm/venv/lib/python3.10/site-packages/ops/framework.py", line 853, in _emit
    self._reemit(event_path)
  File "/var/lib/juju/agents/unit-mysql-router-2/charm/venv/lib/python3.10/site-packages/ops/framework.py", line 942, in _reemit
    custom_handler(event)
  File "/var/lib/juju/agents/unit-mysql-router-2/charm/lib/charms/data_platform_libs/v0/data_interfaces.py", line 3141, in _on_relation_changed_event
    getattr(self.on, "database_created").emit(
  File "/var/lib/juju/agents/unit-mysql-router-2/charm/venv/lib/python3.10/site-packages/ops/framework.py", line 351, in emit
    framework._emit(event)
  File "/var/lib/juju/agents/unit-mysql-router-2/charm/venv/lib/python3.10/site-packages/ops/framework.py", line 853, in _emit
    self._reemit(event_path)
  File "/var/lib/juju/agents/unit-mysql-router-2/charm/venv/lib/python3.10/site-packages/ops/framework.py", line 942, in _reemit
    custom_handler(event)
  File "/var/lib/juju/agents/unit-mysql-router-2/charm/lib/charms/tempo_coordinator_k8s/v0/charm_tracing.py", line 738, in wrapped_function
    return callable(*args, **kwargs)  # type: ignore
  File "/var/lib/juju/agents/unit-mysql-router-2/charm/src/abstract_charm.py", line 355, in reconcile
    workload_.reconcile(
  File "/var/lib/juju/agents/unit-mysql-router-2/charm/lib/charms/tempo_coordinator_k8s/v0/charm_tracing.py", line 738, in wrapped_function
    return callable(*args, **kwargs)  # type: ignore
  File "/var/lib/juju/agents/unit-mysql-router-2/charm/src/workload.py", line 399, in reconcile
    self._enable_router(event=event, tls=tls, unit_name=unit_name)
  File "/var/lib/juju/agents/unit-mysql-router-2/charm/lib/charms/tempo_coordinator_k8s/v0/charm_tracing.py", line 738, in wrapped_function
    return callable(*args, **kwargs)  # type: ignore
  File "/var/lib/juju/agents/unit-mysql-router-2/charm/src/workload.py", line 331, in _enable_router
    self._cleanup_after_upgrade_or_potential_container_restart()
  File "/var/lib/juju/agents/unit-mysql-router-2/charm/lib/charms/tempo_coordinator_k8s/v0/charm_tracing.py", line 738, in wrapped_function
    return callable(*args, **kwargs)  # type: ignore
  File "/var/lib/juju/agents/unit-mysql-router-2/charm/src/workload.py", line 228, in _cleanup_after_upgrade_or_potential_container_restart
    if user_info := self.shell.get_mysql_router_user_for_unit(self._charm.unit.name):
  File "/var/lib/juju/agents/unit-mysql-router-2/charm/src/mysql_shell/__init__.py", line 167, in get_mysql_router_user_for_unit
    self._run_code(
  File "/var/lib/juju/agents/unit-mysql-router-2/charm/src/mysql_shell/__init__.py", line 74, in _run_code
    self._container.run_mysql_shell(
  File "/var/lib/juju/agents/unit-mysql-router-2/charm/lib/charms/tempo_coordinator_k8s/v0/charm_tracing.py", line 738, in wrapped_function
    return callable(*args, **kwargs)  # type: ignore
  File "/var/lib/juju/agents/unit-mysql-router-2/charm/src/container.py", line 212, in run_mysql_shell
    return self._run_command(args, timeout=timeout, input=input)
  File "/var/lib/juju/agents/unit-mysql-router-2/charm/lib/charms/tempo_coordinator_k8s/v0/charm_tracing.py", line 738, in wrapped_function
    return callable(*args, **kwargs)  # type: ignore
  File "/var/lib/juju/agents/unit-mysql-router-2/charm/src/snap.py", line 272, in _run_command
    raise container.CalledProcessError(
container.CalledProcessError: Command '['charmed-mysql.mysqlsh', '--passwords-from-stdin', '--uri', 'relation-8_7ae48bc246f54a6@:3306', '--python', '--file', '/tmp/mysqlsh_script.py']' returned non-zero exit status 1.
unit-mysql-router-1: 01:49:37 ERROR juju.worker.uniter.operation hook "backend-database-relation-changed" (via hook dispatching script: dispatch) failed: exit status 1
unit-mysql-router-3: 01:49:38 ERROR unit.mysql-router/3.juju-log backend-database:8: Failed to run MySQL Shell script:
import json
import mysqlsh
import traceback

try:
    # Disable wizards in this script, since it will be invoked without --no-wizard
    shell.options.set('useWizards', False)
    import json

    result = session.run_sql(
        "SELECT USER, ATTRIBUTE->>'$.router_id' FROM INFORMATION_SCHEMA.USER_ATTRIBUTES WHERE ATTRIBUTE->'$.created_by_user'='relation-8_7ae48bc246f54a6' AND ATTRIBUTE->'$.created_by_juju_unit'='mysql-router/3'"
    )
    rows = result.fetch_all()
    # mysqlsh objects are weirdâ€”they quack (i.e. duck typing) like standard Python objects (e.g. list,
    # dict), but do not serialize to JSON correctly.
    # Cast to str & load from JSON str before serializing
    rows = json.loads(str(rows))
    with open("/tmp/mysqlsh_output.json", "w") as file:
        json.dump(rows, file)
except mysqlsh.DBError as exception:
    error = {
        "message": str(exception),
        "code": exception.code,
        "traceback_message": "".join(traceback.format_exception(exception)),
    }
else:
    error = None
with open("/tmp/mysqlsh_error.json", "w") as file:
    json.dump(error, file)

stderr:
[31mERROR: [0mFailed to retrieve the password: Process "mysql_config_editor" finished with exit code 1: mysql_config_editor: Can't create/write to file '/root/snap/charmed-mysql/139/.mylogin.cnf' (OS errno 13 - Permission denied)
couldn't create the login file : Permission denied
mysql_config_editor: Error on close of '<fd out of range>' (OS errno 9 - Bad file descriptor)
operation failed. : Bad file descriptor
MySQL Error 2005: No such host is known ''

Traceback (most recent call last):
  File "/var/lib/juju/agents/unit-mysql-router-3/charm/src/snap.py", line 263, in _run_command
    output = subprocess.run(
  File "/usr/lib/python3.10/subprocess.py", line 526, in run
    raise CalledProcessError(retcode, process.args,
subprocess.CalledProcessError: Command '['charmed-mysql.mysqlsh', '--passwords-from-stdin', '--uri', 'relation-8_7ae48bc246f54a6@:3306', '--python', '--file', '/tmp/mysqlsh_script.py']' returned non-zero exit status 1.

During handling of the above exception, another exception occurred:

Traceback (most recent call last):
  File "/var/lib/juju/agents/unit-mysql-router-3/charm/src/mysql_shell/__init__.py", line 74, in _run_code
    self._container.run_mysql_shell(
  File "/var/lib/juju/agents/unit-mysql-router-3/charm/lib/charms/tempo_coordinator_k8s/v0/charm_tracing.py", line 738, in wrapped_function
    return callable(*args, **kwargs)  # type: ignore
  File "/var/lib/juju/agents/unit-mysql-router-3/charm/src/container.py", line 212, in run_mysql_shell
    return self._run_command(args, timeout=timeout, input=input)
  File "/var/lib/juju/agents/unit-mysql-router-3/charm/lib/charms/tempo_coordinator_k8s/v0/charm_tracing.py", line 738, in wrapped_function
    return callable(*args, **kwargs)  # type: ignore
  File "/var/lib/juju/agents/unit-mysql-router-3/charm/src/snap.py", line 272, in _run_command
    raise container.CalledProcessError(
container.CalledProcessError: Command '['charmed-mysql.mysqlsh', '--passwords-from-stdin', '--uri', 'relation-8_7ae48bc246f54a6@:3306', '--python', '--file', '/tmp/mysqlsh_script.py']' returned non-zero exit status 1.
unit-mysql-router-2: 01:49:38 ERROR juju.worker.uniter.operation hook "backend-database-relation-changed" (via hook dispatching script: dispatch) failed: exit status 1
unit-mysql-router-3: 01:49:38 ERROR unit.mysql-router/3.juju-log backend-database:8: Uncaught exception while in charm code:
Traceback (most recent call last):
  File "/var/lib/juju/agents/unit-mysql-router-3/charm/src/snap.py", line 263, in _run_command
    output = subprocess.run(
  File "/usr/lib/python3.10/subprocess.py", line 526, in run
    raise CalledProcessError(retcode, process.args,
subprocess.CalledProcessError: Command '['charmed-mysql.mysqlsh', '--passwords-from-stdin', '--uri', 'relation-8_7ae48bc246f54a6@:3306', '--python', '--file', '/tmp/mysqlsh_script.py']' returned non-zero exit status 1.

During handling of the above exception, another exception occurred:

Traceback (most recent call last):
  File "/var/lib/juju/agents/unit-mysql-router-3/charm/src/charm.py", line 235, in <module>
    ops.main.main(MachineSubordinateRouterCharm)
  File "/var/lib/juju/agents/unit-mysql-router-3/charm/venv/lib/python3.10/site-packages/ops/main.py", line 436, in main
    _emit_charm_event(charm, dispatcher.event_name)
  File "/var/lib/juju/agents/unit-mysql-router-3/charm/venv/lib/python3.10/site-packages/ops/main.py", line 144, in _emit_charm_event
    event_to_emit.emit(*args, **kwargs)
  File "/var/lib/juju/agents/unit-mysql-router-3/charm/venv/lib/python3.10/site-packages/ops/framework.py", line 351, in emit
    framework._emit(event)
  File "/var/lib/juju/agents/unit-mysql-router-3/charm/venv/lib/python3.10/site-packages/ops/framework.py", line 853, in _emit
    self._reemit(event_path)
  File "/var/lib/juju/agents/unit-mysql-router-3/charm/venv/lib/python3.10/site-packages/ops/framework.py", line 942, in _reemit
    custom_handler(event)
  File "/var/lib/juju/agents/unit-mysql-router-3/charm/lib/charms/data_platform_libs/v0/data_interfaces.py", line 3141, in _on_relation_changed_event
    getattr(self.on, "database_created").emit(
  File "/var/lib/juju/agents/unit-mysql-router-3/charm/venv/lib/python3.10/site-packages/ops/framework.py", line 351, in emit
    framework._emit(event)
  File "/var/lib/juju/agents/unit-mysql-router-3/charm/venv/lib/python3.10/site-packages/ops/framework.py", line 853, in _emit
    self._reemit(event_path)
  File "/var/lib/juju/agents/unit-mysql-router-3/charm/venv/lib/python3.10/site-packages/ops/framework.py", line 942, in _reemit
    custom_handler(event)
  File "/var/lib/juju/agents/unit-mysql-router-3/charm/lib/charms/tempo_coordinator_k8s/v0/charm_tracing.py", line 738, in wrapped_function
    return callable(*args, **kwargs)  # type: ignore
  File "/var/lib/juju/agents/unit-mysql-router-3/charm/src/abstract_charm.py", line 355, in reconcile
    workload_.reconcile(
  File "/var/lib/juju/agents/unit-mysql-router-3/charm/lib/charms/tempo_coordinator_k8s/v0/charm_tracing.py", line 738, in wrapped_function
    return callable(*args, **kwargs)  # type: ignore
  File "/var/lib/juju/agents/unit-mysql-router-3/charm/src/workload.py", line 399, in reconcile
    self._enable_router(event=event, tls=tls, unit_name=unit_name)
  File "/var/lib/juju/agents/unit-mysql-router-3/charm/lib/charms/tempo_coordinator_k8s/v0/charm_tracing.py", line 738, in wrapped_function
    return callable(*args, **kwargs)  # type: ignore
  File "/var/lib/juju/agents/unit-mysql-router-3/charm/src/workload.py", line 331, in _enable_router
    self._cleanup_after_upgrade_or_potential_container_restart()
  File "/var/lib/juju/agents/unit-mysql-router-3/charm/lib/charms/tempo_coordinator_k8s/v0/charm_tracing.py", line 738, in wrapped_function
    return callable(*args, **kwargs)  # type: ignore
  File "/var/lib/juju/agents/unit-mysql-router-3/charm/src/workload.py", line 228, in _cleanup_after_upgrade_or_potential_container_restart
    if user_info := self.shell.get_mysql_router_user_for_unit(self._charm.unit.name):
  File "/var/lib/juju/agents/unit-mysql-router-3/charm/src/mysql_shell/__init__.py", line 167, in get_mysql_router_user_for_unit
    self._run_code(
  File "/var/lib/juju/agents/unit-mysql-router-3/charm/src/mysql_shell/__init__.py", line 74, in _run_code
    self._container.run_mysql_shell(
  File "/var/lib/juju/agents/unit-mysql-router-3/charm/lib/charms/tempo_coordinator_k8s/v0/charm_tracing.py", line 738, in wrapped_function
    return callable(*args, **kwargs)  # type: ignore
  File "/var/lib/juju/agents/unit-mysql-router-3/charm/src/container.py", line 212, in run_mysql_shell
    return self._run_command(args, timeout=timeout, input=input)
  File "/var/lib/juju/agents/unit-mysql-router-3/charm/lib/charms/tempo_coordinator_k8s/v0/charm_tracing.py", line 738, in wrapped_function
    return callable(*args, **kwargs)  # type: ignore
  File "/var/lib/juju/agents/unit-mysql-router-3/charm/src/snap.py", line 272, in _run_command
    raise container.CalledProcessError(
container.CalledProcessError: Command '['charmed-mysql.mysqlsh', '--passwords-from-stdin', '--uri', 'relation-8_7ae48bc246f54a6@:3306', '--python', '--file', '/tmp/mysqlsh_script.py']' returned non-zero exit status 1.
unit-mysql-router-0: 01:49:38 ERROR unit.mysql-router/0.juju-log backend-database:8: Failed to run MySQL Shell script:
import json
import mysqlsh
import traceback

try:
    # Disable wizards in this script, since it will be invoked without --no-wizard
    shell.options.set('useWizards', False)
    session.run_sql("DROP USER IF EXISTS `relation-8_7ae48bc246f54a6-9`")

except mysqlsh.DBError as exception:
    error = {
        "message": str(exception),
        "code": exception.code,
        "traceback_message": "".join(traceback.format_exception(exception)),
    }
else:
    error = None
with open("/tmp/mysqlsh_error.json", "w") as file:
    json.dump(error, file)

stderr:
[31mERROR: [0mFailed to retrieve the password: Process "mysql_config_editor" finished with exit code 1: mysql_config_editor: Can't create/write to file '/root/snap/charmed-mysql/139/.mylogin.cnf' (OS errno 13 - Permission denied)
couldn't create the login file : Permission denied
mysql_config_editor: Error on close of '<fd out of range>' (OS errno 9 - Bad file descriptor)
operation failed. : Bad file descriptor
MySQL Error 2005: No such host is known ''

Traceback (most recent call last):
  File "/var/lib/juju/agents/unit-mysql-router-0/charm/src/snap.py", line 263, in _run_command
    output = subprocess.run(
  File "/usr/lib/python3.10/subprocess.py", line 526, in run
    raise CalledProcessError(retcode, process.args,
subprocess.CalledProcessError: Command '['charmed-mysql.mysqlsh', '--passwords-from-stdin', '--uri', 'relation-8_7ae48bc246f54a6@:3306', '--python', '--file', '/tmp/mysqlsh_script.py']' returned non-zero exit status 1.

During handling of the above exception, another exception occurred:

Traceback (most recent call last):
  File "/var/lib/juju/agents/unit-mysql-router-0/charm/src/mysql_shell/__init__.py", line 74, in _run_code
    self._container.run_mysql_shell(
  File "/var/lib/juju/agents/unit-mysql-router-0/charm/lib/charms/tempo_coordinator_k8s/v0/charm_tracing.py", line 738, in wrapped_function
    return callable(*args, **kwargs)  # type: ignore
  File "/var/lib/juju/agents/unit-mysql-router-0/charm/src/container.py", line 212, in run_mysql_shell
    return self._run_command(args, timeout=timeout, input=input)
  File "/var/lib/juju/agents/unit-mysql-router-0/charm/lib/charms/tempo_coordinator_k8s/v0/charm_tracing.py", line 738, in wrapped_function
    return callable(*args, **kwargs)  # type: ignore
  File "/var/lib/juju/agents/unit-mysql-router-0/charm/src/snap.py", line 272, in _run_command
    raise container.CalledProcessError(
container.CalledProcessError: Command '['charmed-mysql.mysqlsh', '--passwords-from-stdin', '--uri', 'relation-8_7ae48bc246f54a6@:3306', '--python', '--file', '/tmp/mysqlsh_script.py']' returned non-zero exit status 1.
unit-mysql-router-0: 01:49:38 ERROR unit.mysql-router/0.juju-log backend-database:8: Uncaught exception while in charm code:
Traceback (most recent call last):
  File "/var/lib/juju/agents/unit-mysql-router-0/charm/src/snap.py", line 263, in _run_command
    output = subprocess.run(
  File "/usr/lib/python3.10/subprocess.py", line 526, in run
    raise CalledProcessError(retcode, process.args,
subprocess.CalledProcessError: Command '['charmed-mysql.mysqlsh', '--passwords-from-stdin', '--uri', 'relation-8_7ae48bc246f54a6@:3306', '--python', '--file', '/tmp/mysqlsh_script.py']' returned non-zero exit status 1.

During handling of the above exception, another exception occurred:

Traceback (most recent call last):
  File "/var/lib/juju/agents/unit-mysql-router-0/charm/src/charm.py", line 235, in <module>
    ops.main.main(MachineSubordinateRouterCharm)
  File "/var/lib/juju/agents/unit-mysql-router-0/charm/venv/lib/python3.10/site-packages/ops/main.py", line 436, in main
    _emit_charm_event(charm, dispatcher.event_name)
  File "/var/lib/juju/agents/unit-mysql-router-0/charm/venv/lib/python3.10/site-packages/ops/main.py", line 144, in _emit_charm_event
    event_to_emit.emit(*args, **kwargs)
  File "/var/lib/juju/agents/unit-mysql-router-0/charm/venv/lib/python3.10/site-packages/ops/framework.py", line 351, in emit
    framework._emit(event)
  File "/var/lib/juju/agents/unit-mysql-router-0/charm/venv/lib/python3.10/site-packages/ops/framework.py", line 853, in _emit
    self._reemit(event_path)
  File "/var/lib/juju/agents/unit-mysql-router-0/charm/venv/lib/python3.10/site-packages/ops/framework.py", line 942, in _reemit
    custom_handler(event)
  File "/var/lib/juju/agents/unit-mysql-router-0/charm/lib/charms/data_platform_libs/v0/data_interfaces.py", line 3141, in _on_relation_changed_event
    getattr(self.on, "database_created").emit(
  File "/var/lib/juju/agents/unit-mysql-router-0/charm/venv/lib/python3.10/site-packages/ops/framework.py", line 351, in emit
    framework._emit(event)
  File "/var/lib/juju/agents/unit-mysql-router-0/charm/venv/lib/python3.10/site-packages/ops/framework.py", line 853, in _emit
    self._reemit(event_path)
  File "/var/lib/juju/agents/unit-mysql-router-0/charm/venv/lib/python3.10/site-packages/ops/framework.py", line 942, in _reemit
    custom_handler(event)
  File "/var/lib/juju/agents/unit-mysql-router-0/charm/lib/charms/tempo_coordinator_k8s/v0/charm_tracing.py", line 738, in wrapped_function
    return callable(*args, **kwargs)  # type: ignore
  File "/var/lib/juju/agents/unit-mysql-router-0/charm/src/abstract_charm.py", line 344, in reconcile
    self._database_provides.reconcile_users(
  File "/var/lib/juju/agents/unit-mysql-router-0/charm/lib/charms/tempo_coordinator_k8s/v0/charm_tracing.py", line 738, in wrapped_function
    return callable(*args, **kwargs)  # type: ignore
  File "/var/lib/juju/agents/unit-mysql-router-0/charm/src/relations/database_providers_wrapper.py", line 77, in reconcile_users
    self._database_provides.reconcile_users(
  File "/var/lib/juju/agents/unit-mysql-router-0/charm/src/relations/database_provides.py", line 306, in reconcile_users
    relation.create_database_and_user(
  File "/var/lib/juju/agents/unit-mysql-router-0/charm/src/relations/database_provides.py", line 123, in create_database_and_user
    shell.delete_user(username, must_exist=False)
  File "/var/lib/juju/agents/unit-mysql-router-0/charm/src/mysql_shell/__init__.py", line 207, in delete_user
    self._run_sql([statement])
  File "/var/lib/juju/agents/unit-mysql-router-0/charm/src/mysql_shell/__init__.py", line 113, in _run_sql
    self._run_code(
  File "/var/lib/juju/agents/unit-mysql-router-0/charm/src/mysql_shell/__init__.py", line 74, in _run_code
    self._container.run_mysql_shell(
  File "/var/lib/juju/agents/unit-mysql-router-0/charm/lib/charms/tempo_coordinator_k8s/v0/charm_tracing.py", line 738, in wrapped_function
    return callable(*args, **kwargs)  # type: ignore
  File "/var/lib/juju/agents/unit-mysql-router-0/charm/src/container.py", line 212, in run_mysql_shell
    return self._run_command(args, timeout=timeout, input=input)
  File "/var/lib/juju/agents/unit-mysql-router-0/charm/lib/charms/tempo_coordinator_k8s/v0/charm_tracing.py", line 738, in wrapped_function
    return callable(*args, **kwargs)  # type: ignore
  File "/var/lib/juju/agents/unit-mysql-router-0/charm/src/snap.py", line 272, in _run_command
    raise container.CalledProcessError(
container.CalledProcessError: Command '['charmed-mysql.mysqlsh', '--passwords-from-stdin', '--uri', 'relation-8_7ae48bc246f54a6@:3306', '--python', '--file', '/tmp/mysqlsh_script.py']' returned non-zero exit status 1.
unit-mysql-router-3: 01:49:38 ERROR juju.worker.uniter.operation hook "backend-database-relation-changed" (via hook dispatching script: dispatch) failed: exit status 1
unit-mysql-router-0: 01:49:38 ERROR juju.worker.uniter.operation hook "backend-database-relation-changed" (via hook dispatching script: dispatch) failed: exit status 1
unit-mysql-router-1: 01:49:45 ERROR unit.mysql-router/1.juju-log backend-database:8: Failed to run MySQL Shell script:
import json
import mysqlsh
import traceback

try:
    # Disable wizards in this script, since it will be invoked without --no-wizard
    shell.options.set('useWizards', False)
    import json

    result = session.run_sql(
        "SELECT USER, ATTRIBUTE->>'$.router_id' FROM INFORMATION_SCHEMA.USER_ATTRIBUTES WHERE ATTRIBUTE->'$.created_by_user'='relation-8_7ae48bc246f54a6' AND ATTRIBUTE->'$.created_by_juju_unit'='mysql-router/1'"
    )
    rows = result.fetch_all()
    # mysqlsh objects are weirdâ€”they quack (i.e. duck typing) like standard Python objects (e.g. list,
    # dict), but do not serialize to JSON correctly.
    # Cast to str & load from JSON str before serializing
    rows = json.loads(str(rows))
    with open("/tmp/mysqlsh_output.json", "w") as file:
        json.dump(rows, file)
except mysqlsh.DBError as exception:
    error = {
        "message": str(exception),
        "code": exception.code,
        "traceback_message": "".join(traceback.format_exception(exception)),
    }
else:
    error = None
with open("/tmp/mysqlsh_error.json", "w") as file:
    json.dump(error, file)

stderr:
[31mERROR: [0mFailed to retrieve the password: Process "mysql_config_editor" finished with exit code 1: mysql_config_editor: Can't create/write to file '/root/snap/charmed-mysql/139/.mylogin.cnf' (OS errno 13 - Permission denied)
couldn't create the login file : Permission denied
mysql_config_editor: Error on close of '<fd out of range>' (OS errno 9 - Bad file descriptor)
operation failed. : Bad file descriptor
MySQL Error 2005: No such host is known ''

Traceback (most recent call last):
  File "/var/lib/juju/agents/unit-mysql-router-1/charm/src/snap.py", line 263, in _run_command
    output = subprocess.run(
  File "/usr/lib/python3.10/subprocess.py", line 526, in run
    raise CalledProcessError(retcode, process.args,
subprocess.CalledProcessError: Command '['charmed-mysql.mysqlsh', '--passwords-from-stdin', '--uri', 'relation-8_7ae48bc246f54a6@:3306', '--python', '--file', '/tmp/mysqlsh_script.py']' returned non-zero exit status 1.

During handling of the above exception, another exception occurred:

Traceback (most recent call last):
  File "/var/lib/juju/agents/unit-mysql-router-1/charm/src/mysql_shell/__init__.py", line 74, in _run_code
    self._container.run_mysql_shell(
  File "/var/lib/juju/agents/unit-mysql-router-1/charm/lib/charms/tempo_coordinator_k8s/v0/charm_tracing.py", line 738, in wrapped_function
    return callable(*args, **kwargs)  # type: ignore
  File "/var/lib/juju/agents/unit-mysql-router-1/charm/src/container.py", line 212, in run_mysql_shell
    return self._run_command(args, timeout=timeout, input=input)
  File "/var/lib/juju/agents/unit-mysql-router-1/charm/lib/charms/tempo_coordinator_k8s/v0/charm_tracing.py", line 738, in wrapped_function
    return callable(*args, **kwargs)  # type: ignore
  File "/var/lib/juju/agents/unit-mysql-router-1/charm/src/snap.py", line 272, in _run_command
    raise container.CalledProcessError(
container.CalledProcessError: Command '['charmed-mysql.mysqlsh', '--passwords-from-stdin', '--uri', 'relation-8_7ae48bc246f54a6@:3306', '--python', '--file', '/tmp/mysqlsh_script.py']' returned non-zero exit status 1.
unit-mysql-router-1: 01:49:45 ERROR unit.mysql-router/1.juju-log backend-database:8: Uncaught exception while in charm code:
Traceback (most recent call last):
  File "/var/lib/juju/agents/unit-mysql-router-1/charm/src/snap.py", line 263, in _run_command
    output = subprocess.run(
  File "/usr/lib/python3.10/subprocess.py", line 526, in run
    raise CalledProcessError(retcode, process.args,
subprocess.CalledProcessError: Command '['charmed-mysql.mysqlsh', '--passwords-from-stdin', '--uri', 'relation-8_7ae48bc246f54a6@:3306', '--python', '--file', '/tmp/mysqlsh_script.py']' returned non-zero exit status 1.

During handling of the above exception, another exception occurred:

Traceback (most recent call last):
  File "/var/lib/juju/agents/unit-mysql-router-1/charm/src/charm.py", line 235, in <module>
    ops.main.main(MachineSubordinateRouterCharm)
  File "/var/lib/juju/agents/unit-mysql-router-1/charm/venv/lib/python3.10/site-packages/ops/main.py", line 436, in main
    _emit_charm_event(charm, dispatcher.event_name)
  File "/var/lib/juju/agents/unit-mysql-router-1/charm/venv/lib/python3.10/site-packages/ops/main.py", line 144, in _emit_charm_event
    event_to_emit.emit(*args, **kwargs)
  File "/var/lib/juju/agents/unit-mysql-router-1/charm/venv/lib/python3.10/site-packages/ops/framework.py", line 351, in emit
    framework._emit(event)
  File "/var/lib/juju/agents/unit-mysql-router-1/charm/venv/lib/python3.10/site-packages/ops/framework.py", line 853, in _emit
    self._reemit(event_path)
  File "/var/lib/juju/agents/unit-mysql-router-1/charm/venv/lib/python3.10/site-packages/ops/framework.py", line 942, in _reemit
    custom_handler(event)
  File "/var/lib/juju/agents/unit-mysql-router-1/charm/lib/charms/data_platform_libs/v0/data_interfaces.py", line 3141, in _on_relation_changed_event
    getattr(self.on, "database_created").emit(
  File "/var/lib/juju/agents/unit-mysql-router-1/charm/venv/lib/python3.10/site-packages/ops/framework.py", line 351, in emit
    framework._emit(event)
  File "/var/lib/juju/agents/unit-mysql-router-1/charm/venv/lib/python3.10/site-packages/ops/framework.py", line 853, in _emit
    self._reemit(event_path)
  File "/var/lib/juju/agents/unit-mysql-router-1/charm/venv/lib/python3.10/site-packages/ops/framework.py", line 942, in _reemit
    custom_handler(event)
  File "/var/lib/juju/agents/unit-mysql-router-1/charm/lib/charms/tempo_coordinator_k8s/v0/charm_tracing.py", line 738, in wrapped_function
    return callable(*args, **kwargs)  # type: ignore
  File "/var/lib/juju/agents/unit-mysql-router-1/charm/src/abstract_charm.py", line 355, in reconcile
    workload_.reconcile(
  File "/var/lib/juju/agents/unit-mysql-router-1/charm/lib/charms/tempo_coordinator_k8s/v0/charm_tracing.py", line 738, in wrapped_function
    return callable(*args, **kwargs)  # type: ignore
  File "/var/lib/juju/agents/unit-mysql-router-1/charm/src/workload.py", line 399, in reconcile
    self._enable_router(event=event, tls=tls, unit_name=unit_name)
  File "/var/lib/juju/agents/unit-mysql-router-1/charm/lib/charms/tempo_coordinator_k8s/v0/charm_tracing.py", line 738, in wrapped_function
    return callable(*args, **kwargs)  # type: ignore
  File "/var/lib/juju/agents/unit-mysql-router-1/charm/src/workload.py", line 331, in _enable_router
    self._cleanup_after_upgrade_or_potential_container_restart()
  File "/var/lib/juju/agents/unit-mysql-router-1/charm/lib/charms/tempo_coordinator_k8s/v0/charm_tracing.py", line 738, in wrapped_function
    return callable(*args, **kwargs)  # type: ignore
  File "/var/lib/juju/agents/unit-mysql-router-1/charm/src/workload.py", line 228, in _cleanup_after_upgrade_or_potential_container_restart
    if user_info := self.shell.get_mysql_router_user_for_unit(self._charm.unit.name):
  File "/var/lib/juju/agents/unit-mysql-router-1/charm/src/mysql_shell/__init__.py", line 167, in get_mysql_router_user_for_unit
    self._run_code(
  File "/var/lib/juju/agents/unit-mysql-router-1/charm/src/mysql_shell/__init__.py", line 74, in _run_code
    self._container.run_mysql_shell(
  File "/var/lib/juju/agents/unit-mysql-router-1/charm/lib/charms/tempo_coordinator_k8s/v0/charm_tracing.py", line 738, in wrapped_function
    return callable(*args, **kwargs)  # type: ignore
  File "/var/lib/juju/agents/unit-mysql-router-1/charm/src/container.py", line 212, in run_mysql_shell
    return self._run_command(args, timeout=timeout, input=input)
  File "/var/lib/juju/agents/unit-mysql-router-1/charm/lib/charms/tempo_coordinator_k8s/v0/charm_tracing.py", line 738, in wrapped_function
    return callable(*args, **kwargs)  # type: ignore
  File "/var/lib/juju/agents/unit-mysql-router-1/charm/src/snap.py", line 272, in _run_command
    raise container.CalledProcessError(
container.CalledProcessError: Command '['charmed-mysql.mysqlsh', '--passwords-from-stdin', '--uri', 'relation-8_7ae48bc246f54a6@:3306', '--python', '--file', '/tmp/mysqlsh_script.py']' returned non-zero exit status 1.
unit-mysql-router-1: 01:49:45 ERROR juju.worker.uniter.operation hook "backend-database-relation-changed" (via hook dispatching script: dispatch) failed: exit status 1
unit-mysql-router-2: 01:49:45 ERROR unit.mysql-router/2.juju-log backend-database:8: Failed to run MySQL Shell script:
import json
import mysqlsh
import traceback

try:
    # Disable wizards in this script, since it will be invoked without --no-wizard
    shell.options.set('useWizards', False)
    import json

    result = session.run_sql(
        "SELECT USER, ATTRIBUTE->>'$.router_id' FROM INFORMATION_SCHEMA.USER_ATTRIBUTES WHERE ATTRIBUTE->'$.created_by_user'='relation-8_7ae48bc246f54a6' AND ATTRIBUTE->'$.created_by_juju_unit'='mysql-router/2'"
    )
    rows = result.fetch_all()
    # mysqlsh objects are weirdâ€”they quack (i.e. duck typing) like standard Python objects (e.g. list,
    # dict), but do not serialize to JSON correctly.
    # Cast to str & load from JSON str before serializing
    rows = json.loads(str(rows))
    with open("/tmp/mysqlsh_output.json", "w") as file:
        json.dump(rows, file)
except mysqlsh.DBError as exception:
    error = {
        "message": str(exception),
        "code": exception.code,
        "traceback_message": "".join(traceback.format_exception(exception)),
    }
else:
    error = None
with open("/tmp/mysqlsh_error.json", "w") as file:
    json.dump(error, file)

stderr:
[31mERROR: [0mFailed to retrieve the password: Process "mysql_config_editor" finished with exit code 1: mysql_config_editor: Can't create/write to file '/root/snap/charmed-mysql/139/.mylogin.cnf' (OS errno 13 - Permission denied)
couldn't create the login file : Permission denied
mysql_config_editor: Error on close of '<fd out of range>' (OS errno 9 - Bad file descriptor)
operation failed. : Bad file descriptor
MySQL Error 2005: No such host is known ''

Traceback (most recent call last):
  File "/var/lib/juju/agents/unit-mysql-router-2/charm/src/snap.py", line 263, in _run_command
    output = subprocess.run(
  File "/usr/lib/python3.10/subprocess.py", line 526, in run
    raise CalledProcessError(retcode, process.args,
subprocess.CalledProcessError: Command '['charmed-mysql.mysqlsh', '--passwords-from-stdin', '--uri', 'relation-8_7ae48bc246f54a6@:3306', '--python', '--file', '/tmp/mysqlsh_script.py']' returned non-zero exit status 1.

During handling of the above exception, another exception occurred:

Traceback (most recent call last):
  File "/var/lib/juju/agents/unit-mysql-router-2/charm/src/mysql_shell/__init__.py", line 74, in _run_code
    self._container.run_mysql_shell(
  File "/var/lib/juju/agents/unit-mysql-router-2/charm/lib/charms/tempo_coordinator_k8s/v0/charm_tracing.py", line 738, in wrapped_function
    return callable(*args, **kwargs)  # type: ignore
  File "/var/lib/juju/agents/unit-mysql-router-2/charm/src/container.py", line 212, in run_mysql_shell
    return self._run_command(args, timeout=timeout, input=input)
  File "/var/lib/juju/agents/unit-mysql-router-2/charm/lib/charms/tempo_coordinator_k8s/v0/charm_tracing.py", line 738, in wrapped_function
    return callable(*args, **kwargs)  # type: ignore
  File "/var/lib/juju/agents/unit-mysql-router-2/charm/src/snap.py", line 272, in _run_command
    raise container.CalledProcessError(
container.CalledProcessError: Command '['charmed-mysql.mysqlsh', '--passwords-from-stdin', '--uri', 'relation-8_7ae48bc246f54a6@:3306', '--python', '--file', '/tmp/mysqlsh_script.py']' returned non-zero exit status 1.
unit-mysql-router-2: 01:49:45 ERROR unit.mysql-router/2.juju-log backend-database:8: Uncaught exception while in charm code:
Traceback (most recent call last):
  File "/var/lib/juju/agents/unit-mysql-router-2/charm/src/snap.py", line 263, in _run_command
    output = subprocess.run(
  File "/usr/lib/python3.10/subprocess.py", line 526, in run
    raise CalledProcessError(retcode, process.args,
subprocess.CalledProcessError: Command '['charmed-mysql.mysqlsh', '--passwords-from-stdin', '--uri', 'relation-8_7ae48bc246f54a6@:3306', '--python', '--file', '/tmp/mysqlsh_script.py']' returned non-zero exit status 1.

During handling of the above exception, another exception occurred:

Traceback (most recent call last):
  File "/var/lib/juju/agents/unit-mysql-router-2/charm/src/charm.py", line 235, in <module>
    ops.main.main(MachineSubordinateRouterCharm)
  File "/var/lib/juju/agents/unit-mysql-router-2/charm/venv/lib/python3.10/site-packages/ops/main.py", line 436, in main
    _emit_charm_event(charm, dispatcher.event_name)
  File "/var/lib/juju/agents/unit-mysql-router-2/charm/venv/lib/python3.10/site-packages/ops/main.py", line 144, in _emit_charm_event
    event_to_emit.emit(*args, **kwargs)
  File "/var/lib/juju/agents/unit-mysql-router-2/charm/venv/lib/python3.10/site-packages/ops/framework.py", line 351, in emit
    framework._emit(event)
  File "/var/lib/juju/agents/unit-mysql-router-2/charm/venv/lib/python3.10/site-packages/ops/framework.py", line 853, in _emit
    self._reemit(event_path)
  File "/var/lib/juju/agents/unit-mysql-router-2/charm/venv/lib/python3.10/site-packages/ops/framework.py", line 942, in _reemit
    custom_handler(event)
  File "/var/lib/juju/agents/unit-mysql-router-2/charm/lib/charms/data_platform_libs/v0/data_interfaces.py", line 3141, in _on_relation_changed_event
    getattr(self.on, "database_created").emit(
  File "/var/lib/juju/agents/unit-mysql-router-2/charm/venv/lib/python3.10/site-packages/ops/framework.py", line 351, in emit
    framework._emit(event)
  File "/var/lib/juju/agents/unit-mysql-router-2/charm/venv/lib/python3.10/site-packages/ops/framework.py", line 853, in _emit
    self._reemit(event_path)
  File "/var/lib/juju/agents/unit-mysql-router-2/charm/venv/lib/python3.10/site-packages/ops/framework.py", line 942, in _reemit
    custom_handler(event)
  File "/var/lib/juju/agents/unit-mysql-router-2/charm/lib/charms/tempo_coordinator_k8s/v0/charm_tracing.py", line 738, in wrapped_function
    return callable(*args, **kwargs)  # type: ignore
  File "/var/lib/juju/agents/unit-mysql-router-2/charm/src/abstract_charm.py", line 355, in reconcile
    workload_.reconcile(
  File "/var/lib/juju/agents/unit-mysql-router-2/charm/lib/charms/tempo_coordinator_k8s/v0/charm_tracing.py", line 738, in wrapped_function
    return callable(*args, **kwargs)  # type: ignore
  File "/var/lib/juju/agents/unit-mysql-router-2/charm/src/workload.py", line 399, in reconcile
    self._enable_router(event=event, tls=tls, unit_name=unit_name)
  File "/var/lib/juju/agents/unit-mysql-router-2/charm/lib/charms/tempo_coordinator_k8s/v0/charm_tracing.py", line 738, in wrapped_function
    return callable(*args, **kwargs)  # type: ignore
  File "/var/lib/juju/agents/unit-mysql-router-2/charm/src/workload.py", line 331, in _enable_router
    self._cleanup_after_upgrade_or_potential_container_restart()
  File "/var/lib/juju/agents/unit-mysql-router-2/charm/lib/charms/tempo_coordinator_k8s/v0/charm_tracing.py", line 738, in wrapped_function
    return callable(*args, **kwargs)  # type: ignore
  File "/var/lib/juju/agents/unit-mysql-router-2/charm/src/workload.py", line 228, in _cleanup_after_upgrade_or_potential_container_restart
    if user_info := self.shell.get_mysql_router_user_for_unit(self._charm.unit.name):
  File "/var/lib/juju/agents/unit-mysql-router-2/charm/src/mysql_shell/__init__.py", line 167, in get_mysql_router_user_for_unit
    self._run_code(
  File "/var/lib/juju/agents/unit-mysql-router-2/charm/src/mysql_shell/__init__.py", line 74, in _run_code
    self._container.run_mysql_shell(
  File "/var/lib/juju/agents/unit-mysql-router-2/charm/lib/charms/tempo_coordinator_k8s/v0/charm_tracing.py", line 738, in wrapped_function
    return callable(*args, **kwargs)  # type: ignore
  File "/var/lib/juju/agents/unit-mysql-router-2/charm/src/container.py", line 212, in run_mysql_shell
    return self._run_command(args, timeout=timeout, input=input)
  File "/var/lib/juju/agents/unit-mysql-router-2/charm/lib/charms/tempo_coordinator_k8s/v0/charm_tracing.py", line 738, in wrapped_function
    return callable(*args, **kwargs)  # type: ignore
  File "/var/lib/juju/agents/unit-mysql-router-2/charm/src/snap.py", line 272, in _run_command
    raise container.CalledProcessError(
container.CalledProcessError: Command '['charmed-mysql.mysqlsh', '--passwords-from-stdin', '--uri', 'relation-8_7ae48bc246f54a6@:3306', '--python', '--file', '/tmp/mysqlsh_script.py']' returned non-zero exit status 1.
unit-mysql-router-2: 01:49:45 ERROR juju.worker.uniter.operation hook "backend-database-relation-changed" (via hook dispatching script: dispatch) failed: exit status 1
unit-mysql-router-3: 01:49:46 ERROR unit.mysql-router/3.juju-log backend-database:8: Failed to run MySQL Shell script:
import json
import mysqlsh
import traceback

try:
    # Disable wizards in this script, since it will be invoked without --no-wizard
    shell.options.set('useWizards', False)
    import json

    result = session.run_sql(
        "SELECT USER, ATTRIBUTE->>'$.router_id' FROM INFORMATION_SCHEMA.USER_ATTRIBUTES WHERE ATTRIBUTE->'$.created_by_user'='relation-8_7ae48bc246f54a6' AND ATTRIBUTE->'$.created_by_juju_unit'='mysql-router/3'"
    )
    rows = result.fetch_all()
    # mysqlsh objects are weirdâ€”they quack (i.e. duck typing) like standard Python objects (e.g. list,
    # dict), but do not serialize to JSON correctly.
    # Cast to str & load from JSON str before serializing
    rows = json.loads(str(rows))
    with open("/tmp/mysqlsh_output.json", "w") as file:
        json.dump(rows, file)
except mysqlsh.DBError as exception:
    error = {
        "message": str(exception),
        "code": exception.code,
        "traceback_message": "".join(traceback.format_exception(exception)),
    }
else:
    error = None
with open("/tmp/mysqlsh_error.json", "w") as file:
    json.dump(error, file)

stderr:
[31mERROR: [0mFailed to retrieve the password: Process "mysql_config_editor" finished with exit code 1: mysql_config_editor: Can't create/write to file '/root/snap/charmed-mysql/139/.mylogin.cnf' (OS errno 13 - Permission denied)
couldn't create the login file : Permission denied
mysql_config_editor: Error on close of '<fd out of range>' (OS errno 9 - Bad file descriptor)
operation failed. : Bad file descriptor
MySQL Error 2005: No such host is known ''

Traceback (most recent call last):
  File "/var/lib/juju/agents/unit-mysql-router-3/charm/src/snap.py", line 263, in _run_command
    output = subprocess.run(
  File "/usr/lib/python3.10/subprocess.py", line 526, in run
    raise CalledProcessError(retcode, process.args,
subprocess.CalledProcessError: Command '['charmed-mysql.mysqlsh', '--passwords-from-stdin', '--uri', 'relation-8_7ae48bc246f54a6@:3306', '--python', '--file', '/tmp/mysqlsh_script.py']' returned non-zero exit status 1.

During handling of the above exception, another exception occurred:

Traceback (most recent call last):
  File "/var/lib/juju/agents/unit-mysql-router-3/charm/src/mysql_shell/__init__.py", line 74, in _run_code
    self._container.run_mysql_shell(
  File "/var/lib/juju/agents/unit-mysql-router-3/charm/lib/charms/tempo_coordinator_k8s/v0/charm_tracing.py", line 738, in wrapped_function
    return callable(*args, **kwargs)  # type: ignore
  File "/var/lib/juju/agents/unit-mysql-router-3/charm/src/container.py", line 212, in run_mysql_shell
    return self._run_command(args, timeout=timeout, input=input)
  File "/var/lib/juju/agents/unit-mysql-router-3/charm/lib/charms/tempo_coordinator_k8s/v0/charm_tracing.py", line 738, in wrapped_function
    return callable(*args, **kwargs)  # type: ignore
  File "/var/lib/juju/agents/unit-mysql-router-3/charm/src/snap.py", line 272, in _run_command
    raise container.CalledProcessError(
container.CalledProcessError: Command '['charmed-mysql.mysqlsh', '--passwords-from-stdin', '--uri', 'relation-8_7ae48bc246f54a6@:3306', '--python', '--file', '/tmp/mysqlsh_script.py']' returned non-zero exit status 1.
unit-mysql-router-3: 01:49:46 ERROR unit.mysql-router/3.juju-log backend-database:8: Uncaught exception while in charm code:
Traceback (most recent call last):
  File "/var/lib/juju/agents/unit-mysql-router-3/charm/src/snap.py", line 263, in _run_command
    output = subprocess.run(
  File "/usr/lib/python3.10/subprocess.py", line 526, in run
    raise CalledProcessError(retcode, process.args,
subprocess.CalledProcessError: Command '['charmed-mysql.mysqlsh', '--passwords-from-stdin', '--uri', 'relation-8_7ae48bc246f54a6@:3306', '--python', '--file', '/tmp/mysqlsh_script.py']' returned non-zero exit status 1.

During handling of the above exception, another exception occurred:

Traceback (most recent call last):
  File "/var/lib/juju/agents/unit-mysql-router-3/charm/src/charm.py", line 235, in <module>
    ops.main.main(MachineSubordinateRouterCharm)
  File "/var/lib/juju/agents/unit-mysql-router-3/charm/venv/lib/python3.10/site-packages/ops/main.py", line 436, in main
    _emit_charm_event(charm, dispatcher.event_name)
  File "/var/lib/juju/agents/unit-mysql-router-3/charm/venv/lib/python3.10/site-packages/ops/main.py", line 144, in _emit_charm_event
    event_to_emit.emit(*args, **kwargs)
  File "/var/lib/juju/agents/unit-mysql-router-3/charm/venv/lib/python3.10/site-packages/ops/framework.py", line 351, in emit
    framework._emit(event)
  File "/var/lib/juju/agents/unit-mysql-router-3/charm/venv/lib/python3.10/site-packages/ops/framework.py", line 853, in _emit
    self._reemit(event_path)
  File "/var/lib/juju/agents/unit-mysql-router-3/charm/venv/lib/python3.10/site-packages/ops/framework.py", line 942, in _reemit
    custom_handler(event)
  File "/var/lib/juju/agents/unit-mysql-router-3/charm/lib/charms/data_platform_libs/v0/data_interfaces.py", line 3141, in _on_relation_changed_event
    getattr(self.on, "database_created").emit(
  File "/var/lib/juju/agents/unit-mysql-router-3/charm/venv/lib/python3.10/site-packages/ops/framework.py", line 351, in emit
    framework._emit(event)
  File "/var/lib/juju/agents/unit-mysql-router-3/charm/venv/lib/python3.10/site-packages/ops/framework.py", line 853, in _emit
    self._reemit(event_path)
  File "/var/lib/juju/agents/unit-mysql-router-3/charm/venv/lib/python3.10/site-packages/ops/framework.py", line 942, in _reemit
    custom_handler(event)
  File "/var/lib/juju/agents/unit-mysql-router-3/charm/lib/charms/tempo_coordinator_k8s/v0/charm_tracing.py", line 738, in wrapped_function
    return callable(*args, **kwargs)  # type: ignore
  File "/var/lib/juju/agents/unit-mysql-router-3/charm/src/abstract_charm.py", line 355, in reconcile
    workload_.reconcile(
  File "/var/lib/juju/agents/unit-mysql-router-3/charm/lib/charms/tempo_coordinator_k8s/v0/charm_tracing.py", line 738, in wrapped_function
    return callable(*args, **kwargs)  # type: ignore
  File "/var/lib/juju/agents/unit-mysql-router-3/charm/src/workload.py", line 399, in reconcile
    self._enable_router(event=event, tls=tls, unit_name=unit_name)
  File "/var/lib/juju/agents/unit-mysql-router-3/charm/lib/charms/tempo_coordinator_k8s/v0/charm_tracing.py", line 738, in wrapped_function
    return callable(*args, **kwargs)  # type: ignore
  File "/var/lib/juju/agents/unit-mysql-router-3/charm/src/workload.py", line 331, in _enable_router
    self._cleanup_after_upgrade_or_potential_container_restart()
  File "/var/lib/juju/agents/unit-mysql-router-3/charm/lib/charms/tempo_coordinator_k8s/v0/charm_tracing.py", line 738, in wrapped_function
    return callable(*args, **kwargs)  # type: ignore
  File "/var/lib/juju/agents/unit-mysql-router-3/charm/src/workload.py", line 228, in _cleanup_after_upgrade_or_potential_container_restart
    if user_info := self.shell.get_mysql_router_user_for_unit(self._charm.unit.name):
  File "/var/lib/juju/agents/unit-mysql-router-3/charm/src/mysql_shell/__init__.py", line 167, in get_mysql_router_user_for_unit
    self._run_code(
  File "/var/lib/juju/agents/unit-mysql-router-3/charm/src/mysql_shell/__init__.py", line 74, in _run_code
    self._container.run_mysql_shell(
  File "/var/lib/juju/agents/unit-mysql-router-3/charm/lib/charms/tempo_coordinator_k8s/v0/charm_tracing.py", line 738, in wrapped_function
    return callable(*args, **kwargs)  # type: ignore
  File "/var/lib/juju/agents/unit-mysql-router-3/charm/src/container.py", line 212, in run_mysql_shell
    return self._run_command(args, timeout=timeout, input=input)
  File "/var/lib/juju/agents/unit-mysql-router-3/charm/lib/charms/tempo_coordinator_k8s/v0/charm_tracing.py", line 738, in wrapped_function
    return callable(*args, **kwargs)  # type: ignore
  File "/var/lib/juju/agents/unit-mysql-router-3/charm/src/snap.py", line 272, in _run_command
    raise container.CalledProcessError(
container.CalledProcessError: Command '['charmed-mysql.mysqlsh', '--passwords-from-stdin', '--uri', 'relation-8_7ae48bc246f54a6@:3306', '--python', '--file', '/tmp/mysqlsh_script.py']' returned non-zero exit status 1.
unit-mysql-router-0: 01:49:46 ERROR unit.mysql-router/0.juju-log backend-database:8: Failed to run MySQL Shell script:
import json
import mysqlsh
import traceback

try:
    # Disable wizards in this script, since it will be invoked without --no-wizard
    shell.options.set('useWizards', False)
    session.run_sql("DROP USER IF EXISTS `relation-8_7ae48bc246f54a6-9`")

except mysqlsh.DBError as exception:
    error = {
        "message": str(exception),
        "code": exception.code,
        "traceback_message": "".join(traceback.format_exception(exception)),
    }
else:
    error = None
with open("/tmp/mysqlsh_error.json", "w") as file:
    json.dump(error, file)

stderr:
[31mERROR: [0mFailed to retrieve the password: Process "mysql_config_editor" finished with exit code 1: mysql_config_editor: Can't create/write to file '/root/snap/charmed-mysql/139/.mylogin.cnf' (OS errno 13 - Permission denied)
couldn't create the login file : Permission denied
mysql_config_editor: Error on close of '<fd out of range>' (OS errno 9 - Bad file descriptor)
operation failed. : Bad file descriptor
MySQL Error 2005: No such host is known ''

Traceback (most recent call last):
  File "/var/lib/juju/agents/unit-mysql-router-0/charm/src/snap.py", line 263, in _run_command
    output = subprocess.run(
  File "/usr/lib/python3.10/subprocess.py", line 526, in run
    raise CalledProcessError(retcode, process.args,
subprocess.CalledProcessError: Command '['charmed-mysql.mysqlsh', '--passwords-from-stdin', '--uri', 'relation-8_7ae48bc246f54a6@:3306', '--python', '--file', '/tmp/mysqlsh_script.py']' returned non-zero exit status 1.

During handling of the above exception, another exception occurred:

Traceback (most recent call last):
  File "/var/lib/juju/agents/unit-mysql-router-0/charm/src/mysql_shell/__init__.py", line 74, in _run_code
    self._container.run_mysql_shell(
  File "/var/lib/juju/agents/unit-mysql-router-0/charm/lib/charms/tempo_coordinator_k8s/v0/charm_tracing.py", line 738, in wrapped_function
    return callable(*args, **kwargs)  # type: ignore
  File "/var/lib/juju/agents/unit-mysql-router-0/charm/src/container.py", line 212, in run_mysql_shell
    return self._run_command(args, timeout=timeout, input=input)
  File "/var/lib/juju/agents/unit-mysql-router-0/charm/lib/charms/tempo_coordinator_k8s/v0/charm_tracing.py", line 738, in wrapped_function
    return callable(*args, **kwargs)  # type: ignore
  File "/var/lib/juju/agents/unit-mysql-router-0/charm/src/snap.py", line 272, in _run_command
    raise container.CalledProcessError(
container.CalledProcessError: Command '['charmed-mysql.mysqlsh', '--passwords-from-stdin', '--uri', 'relation-8_7ae48bc246f54a6@:3306', '--python', '--file', '/tmp/mysqlsh_script.py']' returned non-zero exit status 1.
unit-mysql-router-0: 01:49:46 ERROR unit.mysql-router/0.juju-log backend-database:8: Uncaught exception while in charm code:
Traceback (most recent call last):
  File "/var/lib/juju/agents/unit-mysql-router-0/charm/src/snap.py", line 263, in _run_command
    output = subprocess.run(
  File "/usr/lib/python3.10/subprocess.py", line 526, in run
    raise CalledProcessError(retcode, process.args,
subprocess.CalledProcessError: Command '['charmed-mysql.mysqlsh', '--passwords-from-stdin', '--uri', 'relation-8_7ae48bc246f54a6@:3306', '--python', '--file', '/tmp/mysqlsh_script.py']' returned non-zero exit status 1.

During handling of the above exception, another exception occurred:

Traceback (most recent call last):
  File "/var/lib/juju/agents/unit-mysql-router-0/charm/src/charm.py", line 235, in <module>
    ops.main.main(MachineSubordinateRouterCharm)
  File "/var/lib/juju/agents/unit-mysql-router-0/charm/venv/lib/python3.10/site-packages/ops/main.py", line 436, in main
    _emit_charm_event(charm, dispatcher.event_name)
  File "/var/lib/juju/agents/unit-mysql-router-0/charm/venv/lib/python3.10/site-packages/ops/main.py", line 144, in _emit_charm_event
    event_to_emit.emit(*args, **kwargs)
  File "/var/lib/juju/agents/unit-mysql-router-0/charm/venv/lib/python3.10/site-packages/ops/framework.py", line 351, in emit
    framework._emit(event)
  File "/var/lib/juju/agents/unit-mysql-router-0/charm/venv/lib/python3.10/site-packages/ops/framework.py", line 853, in _emit
    self._reemit(event_path)
  File "/var/lib/juju/agents/unit-mysql-router-0/charm/venv/lib/python3.10/site-packages/ops/framework.py", line 942, in _reemit
    custom_handler(event)
  File "/var/lib/juju/agents/unit-mysql-router-0/charm/lib/charms/data_platform_libs/v0/data_interfaces.py", line 3141, in _on_relation_changed_event
    getattr(self.on, "database_created").emit(
  File "/var/lib/juju/agents/unit-mysql-router-0/charm/venv/lib/python3.10/site-packages/ops/framework.py", line 351, in emit
    framework._emit(event)
  File "/var/lib/juju/agents/unit-mysql-router-0/charm/venv/lib/python3.10/site-packages/ops/framework.py", line 853, in _emit
    self._reemit(event_path)
  File "/var/lib/juju/agents/unit-mysql-router-0/charm/venv/lib/python3.10/site-packages/ops/framework.py", line 942, in _reemit
    custom_handler(event)
  File "/var/lib/juju/agents/unit-mysql-router-0/charm/lib/charms/tempo_coordinator_k8s/v0/charm_tracing.py", line 738, in wrapped_function
    return callable(*args, **kwargs)  # type: ignore
  File "/var/lib/juju/agents/unit-mysql-router-0/charm/src/abstract_charm.py", line 344, in reconcile
    self._database_provides.reconcile_users(
  File "/var/lib/juju/agents/unit-mysql-router-0/charm/lib/charms/tempo_coordinator_k8s/v0/charm_tracing.py", line 738, in wrapped_function
    return callable(*args, **kwargs)  # type: ignore
  File "/var/lib/juju/agents/unit-mysql-router-0/charm/src/relations/database_providers_wrapper.py", line 77, in reconcile_users
    self._database_provides.reconcile_users(
  File "/var/lib/juju/agents/unit-mysql-router-0/charm/src/relations/database_provides.py", line 306, in reconcile_users
    relation.create_database_and_user(
  File "/var/lib/juju/agents/unit-mysql-router-0/charm/src/relations/database_provides.py", line 123, in create_database_and_user
    shell.delete_user(username, must_exist=False)
  File "/var/lib/juju/agents/unit-mysql-router-0/charm/src/mysql_shell/__init__.py", line 207, in delete_user
    self._run_sql([statement])
  File "/var/lib/juju/agents/unit-mysql-router-0/charm/src/mysql_shell/__init__.py", line 113, in _run_sql
    self._run_code(
  File "/var/lib/juju/agents/unit-mysql-router-0/charm/src/mysql_shell/__init__.py", line 74, in _run_code
    self._container.run_mysql_shell(
  File "/var/lib/juju/agents/unit-mysql-router-0/charm/lib/charms/tempo_coordinator_k8s/v0/charm_tracing.py", line 738, in wrapped_function
    return callable(*args, **kwargs)  # type: ignore
  File "/var/lib/juju/agents/unit-mysql-router-0/charm/src/container.py", line 212, in run_mysql_shell
    return self._run_command(args, timeout=timeout, input=input)
  File "/var/lib/juju/agents/unit-mysql-router-0/charm/lib/charms/tempo_coordinator_k8s/v0/charm_tracing.py", line 738, in wrapped_function
    return callable(*args, **kwargs)  # type: ignore
  File "/var/lib/juju/agents/unit-mysql-router-0/charm/src/snap.py", line 272, in _run_command
    raise container.CalledProcessError(
container.CalledProcessError: Command '['charmed-mysql.mysqlsh', '--passwords-from-stdin', '--uri', 'relation-8_7ae48bc246f54a6@:3306', '--python', '--file', '/tmp/mysqlsh_script.py']' returned non-zero exit status 1.
unit-mysql-router-3: 01:49:46 ERROR juju.worker.uniter.operation hook "backend-database-relation-changed" (via hook dispatching script: dispatch) failed: exit status 1
unit-mysql-router-0: 01:49:46 ERROR juju.worker.uniter.operation hook "backend-database-relation-changed" (via hook dispatching script: dispatch) failed: exit status 1
unit-mysql-router-1: 01:49:57 ERROR unit.mysql-router/1.juju-log backend-database:8: Failed to run MySQL Shell script:
import json
import mysqlsh
import traceback

try:
    # Disable wizards in this script, since it will be invoked without --no-wizard
    shell.options.set('useWizards', False)
    import json

    result = session.run_sql(
        "SELECT USER, ATTRIBUTE->>'$.router_id' FROM INFORMATION_SCHEMA.USER_ATTRIBUTES WHERE ATTRIBUTE->'$.created_by_user'='relation-8_7ae48bc246f54a6' AND ATTRIBUTE->'$.created_by_juju_unit'='mysql-router/1'"
    )
    rows = result.fetch_all()
    # mysqlsh objects are weirdâ€”they quack (i.e. duck typing) like standard Python objects (e.g. list,
    # dict), but do not serialize to JSON correctly.
    # Cast to str & load from JSON str before serializing
    rows = json.loads(str(rows))
    with open("/tmp/mysqlsh_output.json", "w") as file:
        json.dump(rows, file)
except mysqlsh.DBError as exception:
    error = {
        "message": str(exception),
        "code": exception.code,
        "traceback_message": "".join(traceback.format_exception(exception)),
    }
else:
    error = None
with open("/tmp/mysqlsh_error.json", "w") as file:
    json.dump(error, file)

stderr:
[31mERROR: [0mFailed to retrieve the password: Process "mysql_config_editor" finished with exit code 1: mysql_config_editor: Can't create/write to file '/root/snap/charmed-mysql/139/.mylogin.cnf' (OS errno 13 - Permission denied)
couldn't create the login file : Permission denied
mysql_config_editor: Error on close of '<fd out of range>' (OS errno 9 - Bad file descriptor)
operation failed. : Bad file descriptor
MySQL Error 2005: No such host is known ''

Traceback (most recent call last):
  File "/var/lib/juju/agents/unit-mysql-router-1/charm/src/snap.py", line 263, in _run_command
    output = subprocess.run(
  File "/usr/lib/python3.10/subprocess.py", line 526, in run
    raise CalledProcessError(retcode, process.args,
subprocess.CalledProcessError: Command '['charmed-mysql.mysqlsh', '--passwords-from-stdin', '--uri', 'relation-8_7ae48bc246f54a6@:3306', '--python', '--file', '/tmp/mysqlsh_script.py']' returned non-zero exit status 1.

During handling of the above exception, another exception occurred:

Traceback (most recent call last):
  File "/var/lib/juju/agents/unit-mysql-router-1/charm/src/mysql_shell/__init__.py", line 74, in _run_code
    self._container.run_mysql_shell(
  File "/var/lib/juju/agents/unit-mysql-router-1/charm/lib/charms/tempo_coordinator_k8s/v0/charm_tracing.py", line 738, in wrapped_function
    return callable(*args, **kwargs)  # type: ignore
  File "/var/lib/juju/agents/unit-mysql-router-1/charm/src/container.py", line 212, in run_mysql_shell
    return self._run_command(args, timeout=timeout, input=input)
  File "/var/lib/juju/agents/unit-mysql-router-1/charm/lib/charms/tempo_coordinator_k8s/v0/charm_tracing.py", line 738, in wrapped_function
    return callable(*args, **kwargs)  # type: ignore
  File "/var/lib/juju/agents/unit-mysql-router-1/charm/src/snap.py", line 272, in _run_command
    raise container.CalledProcessError(
container.CalledProcessError: Command '['charmed-mysql.mysqlsh', '--passwords-from-stdin', '--uri', 'relation-8_7ae48bc246f54a6@:3306', '--python', '--file', '/tmp/mysqlsh_script.py']' returned non-zero exit status 1.
unit-mysql-router-1: 01:49:57 ERROR unit.mysql-router/1.juju-log backend-database:8: Uncaught exception while in charm code:
Traceback (most recent call last):
  File "/var/lib/juju/agents/unit-mysql-router-1/charm/src/snap.py", line 263, in _run_command
    output = subprocess.run(
  File "/usr/lib/python3.10/subprocess.py", line 526, in run
    raise CalledProcessError(retcode, process.args,
subprocess.CalledProcessError: Command '['charmed-mysql.mysqlsh', '--passwords-from-stdin', '--uri', 'relation-8_7ae48bc246f54a6@:3306', '--python', '--file', '/tmp/mysqlsh_script.py']' returned non-zero exit status 1.

During handling of the above exception, another exception occurred:

Traceback (most recent call last):
  File "/var/lib/juju/agents/unit-mysql-router-1/charm/src/charm.py", line 235, in <module>
    ops.main.main(MachineSubordinateRouterCharm)
  File "/var/lib/juju/agents/unit-mysql-router-1/charm/venv/lib/python3.10/site-packages/ops/main.py", line 436, in main
    _emit_charm_event(charm, dispatcher.event_name)
  File "/var/lib/juju/agents/unit-mysql-router-1/charm/venv/lib/python3.10/site-packages/ops/main.py", line 144, in _emit_charm_event
    event_to_emit.emit(*args, **kwargs)
  File "/var/lib/juju/agents/unit-mysql-router-1/charm/venv/lib/python3.10/site-packages/ops/framework.py", line 351, in emit
    framework._emit(event)
  File "/var/lib/juju/agents/unit-mysql-router-1/charm/venv/lib/python3.10/site-packages/ops/framework.py", line 853, in _emit
    self._reemit(event_path)
  File "/var/lib/juju/agents/unit-mysql-router-1/charm/venv/lib/python3.10/site-packages/ops/framework.py", line 942, in _reemit
    custom_handler(event)
  File "/var/lib/juju/agents/unit-mysql-router-1/charm/lib/charms/data_platform_libs/v0/data_interfaces.py", line 3141, in _on_relation_changed_event
    getattr(self.on, "database_created").emit(
  File "/var/lib/juju/agents/unit-mysql-router-1/charm/venv/lib/python3.10/site-packages/ops/framework.py", line 351, in emit
    framework._emit(event)
  File "/var/lib/juju/agents/unit-mysql-router-1/charm/venv/lib/python3.10/site-packages/ops/framework.py", line 853, in _emit
    self._reemit(event_path)
  File "/var/lib/juju/agents/unit-mysql-router-1/charm/venv/lib/python3.10/site-packages/ops/framework.py", line 942, in _reemit
    custom_handler(event)
  File "/var/lib/juju/agents/unit-mysql-router-1/charm/lib/charms/tempo_coordinator_k8s/v0/charm_tracing.py", line 738, in wrapped_function
    return callable(*args, **kwargs)  # type: ignore
  File "/var/lib/juju/agents/unit-mysql-router-1/charm/src/abstract_charm.py", line 355, in reconcile
    workload_.reconcile(
  File "/var/lib/juju/agents/unit-mysql-router-1/charm/lib/charms/tempo_coordinator_k8s/v0/charm_tracing.py", line 738, in wrapped_function
    return callable(*args, **kwargs)  # type: ignore
  File "/var/lib/juju/agents/unit-mysql-router-1/charm/src/workload.py", line 399, in reconcile
    self._enable_router(event=event, tls=tls, unit_name=unit_name)
  File "/var/lib/juju/agents/unit-mysql-router-1/charm/lib/charms/tempo_coordinator_k8s/v0/charm_tracing.py", line 738, in wrapped_function
    return callable(*args, **kwargs)  # type: ignore
  File "/var/lib/juju/agents/unit-mysql-router-1/charm/src/workload.py", line 331, in _enable_router
    self._cleanup_after_upgrade_or_potential_container_restart()
  File "/var/lib/juju/agents/unit-mysql-router-1/charm/lib/charms/tempo_coordinator_k8s/v0/charm_tracing.py", line 738, in wrapped_function
    return callable(*args, **kwargs)  # type: ignore
  File "/var/lib/juju/agents/unit-mysql-router-1/charm/src/workload.py", line 228, in _cleanup_after_upgrade_or_potential_container_restart
    if user_info := self.shell.get_mysql_router_user_for_unit(self._charm.unit.name):
  File "/var/lib/juju/agents/unit-mysql-router-1/charm/src/mysql_shell/__init__.py", line 167, in get_mysql_router_user_for_unit
    self._run_code(
  File "/var/lib/juju/agents/unit-mysql-router-1/charm/src/mysql_shell/__init__.py", line 74, in _run_code
    self._container.run_mysql_shell(
  File "/var/lib/juju/agents/unit-mysql-router-1/charm/lib/charms/tempo_coordinator_k8s/v0/charm_tracing.py", line 738, in wrapped_function
    return callable(*args, **kwargs)  # type: ignore
  File "/var/lib/juju/agents/unit-mysql-router-1/charm/src/container.py", line 212, in run_mysql_shell
    return self._run_command(args, timeout=timeout, input=input)
  File "/var/lib/juju/agents/unit-mysql-router-1/charm/lib/charms/tempo_coordinator_k8s/v0/charm_tracing.py", line 738, in wrapped_function
    return callable(*args, **kwargs)  # type: ignore
  File "/var/lib/juju/agents/unit-mysql-router-1/charm/src/snap.py", line 272, in _run_command
    raise container.CalledProcessError(
container.CalledProcessError: Command '['charmed-mysql.mysqlsh', '--passwords-from-stdin', '--uri', 'relation-8_7ae48bc246f54a6@:3306', '--python', '--file', '/tmp/mysqlsh_script.py']' returned non-zero exit status 1.
unit-mysql-router-1: 01:49:57 ERROR juju.worker.uniter.operation hook "backend-database-relation-changed" (via hook dispatching script: dispatch) failed: exit status 1
unit-mysql-router-3: 01:49:58 ERROR unit.mysql-router/3.juju-log backend-database:8: Failed to run MySQL Shell script:
import json
import mysqlsh
import traceback

try:
    # Disable wizards in this script, since it will be invoked without --no-wizard
    shell.options.set('useWizards', False)
    import json

    result = session.run_sql(
        "SELECT USER, ATTRIBUTE->>'$.router_id' FROM INFORMATION_SCHEMA.USER_ATTRIBUTES WHERE ATTRIBUTE->'$.created_by_user'='relation-8_7ae48bc246f54a6' AND ATTRIBUTE->'$.created_by_juju_unit'='mysql-router/3'"
    )
    rows = result.fetch_all()
    # mysqlsh objects are weirdâ€”they quack (i.e. duck typing) like standard Python objects (e.g. list,
    # dict), but do not serialize to JSON correctly.
    # Cast to str & load from JSON str before serializing
    rows = json.loads(str(rows))
    with open("/tmp/mysqlsh_output.json", "w") as file:
        json.dump(rows, file)
except mysqlsh.DBError as exception:
    error = {
        "message": str(exception),
        "code": exception.code,
        "traceback_message": "".join(traceback.format_exception(exception)),
    }
else:
    error = None
with open("/tmp/mysqlsh_error.json", "w") as file:
    json.dump(error, file)

stderr:
[31mERROR: [0mFailed to retrieve the password: Process "mysql_config_editor" finished with exit code 1: mysql_config_editor: Can't create/write to file '/root/snap/charmed-mysql/139/.mylogin.cnf' (OS errno 13 - Permission denied)
couldn't create the login file : Permission denied
mysql_config_editor: Error on close of '<fd out of range>' (OS errno 9 - Bad file descriptor)
operation failed. : Bad file descriptor
MySQL Error 2005: No such host is known ''

Traceback (most recent call last):
  File "/var/lib/juju/agents/unit-mysql-router-3/charm/src/snap.py", line 263, in _run_command
    output = subprocess.run(
  File "/usr/lib/python3.10/subprocess.py", line 526, in run
    raise CalledProcessError(retcode, process.args,
subprocess.CalledProcessError: Command '['charmed-mysql.mysqlsh', '--passwords-from-stdin', '--uri', 'relation-8_7ae48bc246f54a6@:3306', '--python', '--file', '/tmp/mysqlsh_script.py']' returned non-zero exit status 1.

During handling of the above exception, another exception occurred:

Traceback (most recent call last):
  File "/var/lib/juju/agents/unit-mysql-router-3/charm/src/mysql_shell/__init__.py", line 74, in _run_code
    self._container.run_mysql_shell(
  File "/var/lib/juju/agents/unit-mysql-router-3/charm/lib/charms/tempo_coordinator_k8s/v0/charm_tracing.py", line 738, in wrapped_function
    return callable(*args, **kwargs)  # type: ignore
  File "/var/lib/juju/agents/unit-mysql-router-3/charm/src/container.py", line 212, in run_mysql_shell
    return self._run_command(args, timeout=timeout, input=input)
  File "/var/lib/juju/agents/unit-mysql-router-3/charm/lib/charms/tempo_coordinator_k8s/v0/charm_tracing.py", line 738, in wrapped_function
    return callable(*args, **kwargs)  # type: ignore
  File "/var/lib/juju/agents/unit-mysql-router-3/charm/src/snap.py", line 272, in _run_command
    raise container.CalledProcessError(
container.CalledProcessError: Command '['charmed-mysql.mysqlsh', '--passwords-from-stdin', '--uri', 'relation-8_7ae48bc246f54a6@:3306', '--python', '--file', '/tmp/mysqlsh_script.py']' returned non-zero exit status 1.
unit-mysql-router-3: 01:49:58 ERROR unit.mysql-router/3.juju-log backend-database:8: Uncaught exception while in charm code:
Traceback (most recent call last):
  File "/var/lib/juju/agents/unit-mysql-router-3/charm/src/snap.py", line 263, in _run_command
    output = subprocess.run(
  File "/usr/lib/python3.10/subprocess.py", line 526, in run
    raise CalledProcessError(retcode, process.args,
subprocess.CalledProcessError: Command '['charmed-mysql.mysqlsh', '--passwords-from-stdin', '--uri', 'relation-8_7ae48bc246f54a6@:3306', '--python', '--file', '/tmp/mysqlsh_script.py']' returned non-zero exit status 1.

During handling of the above exception, another exception occurred:

Traceback (most recent call last):
  File "/var/lib/juju/agents/unit-mysql-router-3/charm/src/charm.py", line 235, in <module>
    ops.main.main(MachineSubordinateRouterCharm)
  File "/var/lib/juju/agents/unit-mysql-router-3/charm/venv/lib/python3.10/site-packages/ops/main.py", line 436, in main
    _emit_charm_event(charm, dispatcher.event_name)
  File "/var/lib/juju/agents/unit-mysql-router-3/charm/venv/lib/python3.10/site-packages/ops/main.py", line 144, in _emit_charm_event
    event_to_emit.emit(*args, **kwargs)
  File "/var/lib/juju/agents/unit-mysql-router-3/charm/venv/lib/python3.10/site-packages/ops/framework.py", line 351, in emit
    framework._emit(event)
  File "/var/lib/juju/agents/unit-mysql-router-3/charm/venv/lib/python3.10/site-packages/ops/framework.py", line 853, in _emit
    self._reemit(event_path)
  File "/var/lib/juju/agents/unit-mysql-router-3/charm/venv/lib/python3.10/site-packages/ops/framework.py", line 942, in _reemit
    custom_handler(event)
  File "/var/lib/juju/agents/unit-mysql-router-3/charm/lib/charms/data_platform_libs/v0/data_interfaces.py", line 3141, in _on_relation_changed_event
    getattr(self.on, "database_created").emit(
  File "/var/lib/juju/agents/unit-mysql-router-3/charm/venv/lib/python3.10/site-packages/ops/framework.py", line 351, in emit
    framework._emit(event)
  File "/var/lib/juju/agents/unit-mysql-router-3/charm/venv/lib/python3.10/site-packages/ops/framework.py", line 853, in _emit
    self._reemit(event_path)
  File "/var/lib/juju/agents/unit-mysql-router-3/charm/venv/lib/python3.10/site-packages/ops/framework.py", line 942, in _reemit
    custom_handler(event)
  File "/var/lib/juju/agents/unit-mysql-router-3/charm/lib/charms/tempo_coordinator_k8s/v0/charm_tracing.py", line 738, in wrapped_function
    return callable(*args, **kwargs)  # type: ignore
  File "/var/lib/juju/agents/unit-mysql-router-3/charm/src/abstract_charm.py", line 355, in reconcile
    workload_.reconcile(
  File "/var/lib/juju/agents/unit-mysql-router-3/charm/lib/charms/tempo_coordinator_k8s/v0/charm_tracing.py", line 738, in wrapped_function
    return callable(*args, **kwargs)  # type: ignore
  File "/var/lib/juju/agents/unit-mysql-router-3/charm/src/workload.py", line 399, in reconcile
    self._enable_router(event=event, tls=tls, unit_name=unit_name)
  File "/var/lib/juju/agents/unit-mysql-router-3/charm/lib/charms/tempo_coordinator_k8s/v0/charm_tracing.py", line 738, in wrapped_function
    return callable(*args, **kwargs)  # type: ignore
  File "/var/lib/juju/agents/unit-mysql-router-3/charm/src/workload.py", line 331, in _enable_router
    self._cleanup_after_upgrade_or_potential_container_restart()
  File "/var/lib/juju/agents/unit-mysql-router-3/charm/lib/charms/tempo_coordinator_k8s/v0/charm_tracing.py", line 738, in wrapped_function
    return callable(*args, **kwargs)  # type: ignore
  File "/var/lib/juju/agents/unit-mysql-router-3/charm/src/workload.py", line 228, in _cleanup_after_upgrade_or_potential_container_restart
    if user_info := self.shell.get_mysql_router_user_for_unit(self._charm.unit.name):
  File "/var/lib/juju/agents/unit-mysql-router-3/charm/src/mysql_shell/__init__.py", line 167, in get_mysql_router_user_for_unit
    self._run_code(
  File "/var/lib/juju/agents/unit-mysql-router-3/charm/src/mysql_shell/__init__.py", line 74, in _run_code
    self._container.run_mysql_shell(
  File "/var/lib/juju/agents/unit-mysql-router-3/charm/lib/charms/tempo_coordinator_k8s/v0/charm_tracing.py", line 738, in wrapped_function
    return callable(*args, **kwargs)  # type: ignore
  File "/var/lib/juju/agents/unit-mysql-router-3/charm/src/container.py", line 212, in run_mysql_shell
    return self._run_command(args, timeout=timeout, input=input)
  File "/var/lib/juju/agents/unit-mysql-router-3/charm/lib/charms/tempo_coordinator_k8s/v0/charm_tracing.py", line 738, in wrapped_function
    return callable(*args, **kwargs)  # type: ignore
  File "/var/lib/juju/agents/unit-mysql-router-3/charm/src/snap.py", line 272, in _run_command
    raise container.CalledProcessError(
container.CalledProcessError: Command '['charmed-mysql.mysqlsh', '--passwords-from-stdin', '--uri', 'relation-8_7ae48bc246f54a6@:3306', '--python', '--file', '/tmp/mysqlsh_script.py']' returned non-zero exit status 1.
unit-mysql-router-2: 01:49:58 ERROR unit.mysql-router/2.juju-log backend-database:8: Failed to run MySQL Shell script:
import json
import mysqlsh
import traceback

try:
    # Disable wizards in this script, since it will be invoked without --no-wizard
    shell.options.set('useWizards', False)
    import json

    result = session.run_sql(
        "SELECT USER, ATTRIBUTE->>'$.router_id' FROM INFORMATION_SCHEMA.USER_ATTRIBUTES WHERE ATTRIBUTE->'$.created_by_user'='relation-8_7ae48bc246f54a6' AND ATTRIBUTE->'$.created_by_juju_unit'='mysql-router/2'"
    )
    rows = result.fetch_all()
    # mysqlsh objects are weirdâ€”they quack (i.e. duck typing) like standard Python objects (e.g. list,
    # dict), but do not serialize to JSON correctly.
    # Cast to str & load from JSON str before serializing
    rows = json.loads(str(rows))
    with open("/tmp/mysqlsh_output.json", "w") as file:
        json.dump(rows, file)
except mysqlsh.DBError as exception:
    error = {
        "message": str(exception),
        "code": exception.code,
        "traceback_message": "".join(traceback.format_exception(exception)),
    }
else:
    error = None
with open("/tmp/mysqlsh_error.json", "w") as file:
    json.dump(error, file)

stderr:
[31mERROR: [0mFailed to retrieve the password: Process "mysql_config_editor" finished with exit code 1: mysql_config_editor: Can't create/write to file '/root/snap/charmed-mysql/139/.mylogin.cnf' (OS errno 13 - Permission denied)
couldn't create the login file : Permission denied
mysql_config_editor: Error on close of '<fd out of range>' (OS errno 9 - Bad file descriptor)
operation failed. : Bad file descriptor
MySQL Error 2005: No such host is known ''

Traceback (most recent call last):
  File "/var/lib/juju/agents/unit-mysql-router-2/charm/src/snap.py", line 263, in _run_command
    output = subprocess.run(
  File "/usr/lib/python3.10/subprocess.py", line 526, in run
    raise CalledProcessError(retcode, process.args,
subprocess.CalledProcessError: Command '['charmed-mysql.mysqlsh', '--passwords-from-stdin', '--uri', 'relation-8_7ae48bc246f54a6@:3306', '--python', '--file', '/tmp/mysqlsh_script.py']' returned non-zero exit status 1.

During handling of the above exception, another exception occurred:

Traceback (most recent call last):
  File "/var/lib/juju/agents/unit-mysql-router-2/charm/src/mysql_shell/__init__.py", line 74, in _run_code
    self._container.run_mysql_shell(
  File "/var/lib/juju/agents/unit-mysql-router-2/charm/lib/charms/tempo_coordinator_k8s/v0/charm_tracing.py", line 738, in wrapped_function
    return callable(*args, **kwargs)  # type: ignore
  File "/var/lib/juju/agents/unit-mysql-router-2/charm/src/container.py", line 212, in run_mysql_shell
    return self._run_command(args, timeout=timeout, input=input)
  File "/var/lib/juju/agents/unit-mysql-router-2/charm/lib/charms/tempo_coordinator_k8s/v0/charm_tracing.py", line 738, in wrapped_function
    return callable(*args, **kwargs)  # type: ignore
  File "/var/lib/juju/agents/unit-mysql-router-2/charm/src/snap.py", line 272, in _run_command
    raise container.CalledProcessError(
container.CalledProcessError: Command '['charmed-mysql.mysqlsh', '--passwords-from-stdin', '--uri', 'relation-8_7ae48bc246f54a6@:3306', '--python', '--file', '/tmp/mysqlsh_script.py']' returned non-zero exit status 1.
unit-mysql-router-2: 01:49:58 ERROR unit.mysql-router/2.juju-log backend-database:8: Uncaught exception while in charm code:
Traceback (most recent call last):
  File "/var/lib/juju/agents/unit-mysql-router-2/charm/src/snap.py", line 263, in _run_command
    output = subprocess.run(
  File "/usr/lib/python3.10/subprocess.py", line 526, in run
    raise CalledProcessError(retcode, process.args,
subprocess.CalledProcessError: Command '['charmed-mysql.mysqlsh', '--passwords-from-stdin', '--uri', 'relation-8_7ae48bc246f54a6@:3306', '--python', '--file', '/tmp/mysqlsh_script.py']' returned non-zero exit status 1.

During handling of the above exception, another exception occurred:

Traceback (most recent call last):
  File "/var/lib/juju/agents/unit-mysql-router-2/charm/src/charm.py", line 235, in <module>
    ops.main.main(MachineSubordinateRouterCharm)
  File "/var/lib/juju/agents/unit-mysql-router-2/charm/venv/lib/python3.10/site-packages/ops/main.py", line 436, in main
    _emit_charm_event(charm, dispatcher.event_name)
  File "/var/lib/juju/agents/unit-mysql-router-2/charm/venv/lib/python3.10/site-packages/ops/main.py", line 144, in _emit_charm_event
    event_to_emit.emit(*args, **kwargs)
  File "/var/lib/juju/agents/unit-mysql-router-2/charm/venv/lib/python3.10/site-packages/ops/framework.py", line 351, in emit
    framework._emit(event)
  File "/var/lib/juju/agents/unit-mysql-router-2/charm/venv/lib/python3.10/site-packages/ops/framework.py", line 853, in _emit
    self._reemit(event_path)
  File "/var/lib/juju/agents/unit-mysql-router-2/charm/venv/lib/python3.10/site-packages/ops/framework.py", line 942, in _reemit
    custom_handler(event)
  File "/var/lib/juju/agents/unit-mysql-router-2/charm/lib/charms/data_platform_libs/v0/data_interfaces.py", line 3141, in _on_relation_changed_event
    getattr(self.on, "database_created").emit(
  File "/var/lib/juju/agents/unit-mysql-router-2/charm/venv/lib/python3.10/site-packages/ops/framework.py", line 351, in emit
    framework._emit(event)
  File "/var/lib/juju/agents/unit-mysql-router-2/charm/venv/lib/python3.10/site-packages/ops/framework.py", line 853, in _emit
    self._reemit(event_path)
  File "/var/lib/juju/agents/unit-mysql-router-2/charm/venv/lib/python3.10/site-packages/ops/framework.py", line 942, in _reemit
    custom_handler(event)
  File "/var/lib/juju/agents/unit-mysql-router-2/charm/lib/charms/tempo_coordinator_k8s/v0/charm_tracing.py", line 738, in wrapped_function
    return callable(*args, **kwargs)  # type: ignore
  File "/var/lib/juju/agents/unit-mysql-router-2/charm/src/abstract_charm.py", line 355, in reconcile
    workload_.reconcile(
  File "/var/lib/juju/agents/unit-mysql-router-2/charm/lib/charms/tempo_coordinator_k8s/v0/charm_tracing.py", line 738, in wrapped_function
    return callable(*args, **kwargs)  # type: ignore
  File "/var/lib/juju/agents/unit-mysql-router-2/charm/src/workload.py", line 399, in reconcile
    self._enable_router(event=event, tls=tls, unit_name=unit_name)
  File "/var/lib/juju/agents/unit-mysql-router-2/charm/lib/charms/tempo_coordinator_k8s/v0/charm_tracing.py", line 738, in wrapped_function
    return callable(*args, **kwargs)  # type: ignore
  File "/var/lib/juju/agents/unit-mysql-router-2/charm/src/workload.py", line 331, in _enable_router
    self._cleanup_after_upgrade_or_potential_container_restart()
  File "/var/lib/juju/agents/unit-mysql-router-2/charm/lib/charms/tempo_coordinator_k8s/v0/charm_tracing.py", line 738, in wrapped_function
    return callable(*args, **kwargs)  # type: ignore
  File "/var/lib/juju/agents/unit-mysql-router-2/charm/src/workload.py", line 228, in _cleanup_after_upgrade_or_potential_container_restart
    if user_info := self.shell.get_mysql_router_user_for_unit(self._charm.unit.name):
  File "/var/lib/juju/agents/unit-mysql-router-2/charm/src/mysql_shell/__init__.py", line 167, in get_mysql_router_user_for_unit
    self._run_code(
  File "/var/lib/juju/agents/unit-mysql-router-2/charm/src/mysql_shell/__init__.py", line 74, in _run_code
    self._container.run_mysql_shell(
  File "/var/lib/juju/agents/unit-mysql-router-2/charm/lib/charms/tempo_coordinator_k8s/v0/charm_tracing.py", line 738, in wrapped_function
    return callable(*args, **kwargs)  # type: ignore
  File "/var/lib/juju/agents/unit-mysql-router-2/charm/src/container.py", line 212, in run_mysql_shell
    return self._run_command(args, timeout=timeout, input=input)
  File "/var/lib/juju/agents/unit-mysql-router-2/charm/lib/charms/tempo_coordinator_k8s/v0/charm_tracing.py", line 738, in wrapped_function
    return callable(*args, **kwargs)  # type: ignore
  File "/var/lib/juju/agents/unit-mysql-router-2/charm/src/snap.py", line 272, in _run_command
    raise container.CalledProcessError(
container.CalledProcessError: Command '['charmed-mysql.mysqlsh', '--passwords-from-stdin', '--uri', 'relation-8_7ae48bc246f54a6@:3306', '--python', '--file', '/tmp/mysqlsh_script.py']' returned non-zero exit status 1.
unit-mysql-router-0: 01:49:58 ERROR unit.mysql-router/0.juju-log backend-database:8: Failed to run MySQL Shell script:
import json
import mysqlsh
import traceback

try:
    # Disable wizards in this script, since it will be invoked without --no-wizard
    shell.options.set('useWizards', False)
    session.run_sql("DROP USER IF EXISTS `relation-8_7ae48bc246f54a6-9`")

except mysqlsh.DBError as exception:
    error = {
        "message": str(exception),
        "code": exception.code,
        "traceback_message": "".join(traceback.format_exception(exception)),
    }
else:
    error = None
with open("/tmp/mysqlsh_error.json", "w") as file:
    json.dump(error, file)

stderr:
[31mERROR: [0mFailed to retrieve the password: Process "mysql_config_editor" finished with exit code 1: mysql_config_editor: Can't create/write to file '/root/snap/charmed-mysql/139/.mylogin.cnf' (OS errno 13 - Permission denied)
couldn't create the login file : Permission denied
mysql_config_editor: Error on close of '<fd out of range>' (OS errno 9 - Bad file descriptor)
operation failed. : Bad file descriptor
MySQL Error 2005: No such host is known ''

Traceback (most recent call last):
  File "/var/lib/juju/agents/unit-mysql-router-0/charm/src/snap.py", line 263, in _run_command
    output = subprocess.run(
  File "/usr/lib/python3.10/subprocess.py", line 526, in run
    raise CalledProcessError(retcode, process.args,
subprocess.CalledProcessError: Command '['charmed-mysql.mysqlsh', '--passwords-from-stdin', '--uri', 'relation-8_7ae48bc246f54a6@:3306', '--python', '--file', '/tmp/mysqlsh_script.py']' returned non-zero exit status 1.

During handling of the above exception, another exception occurred:

Traceback (most recent call last):
  File "/var/lib/juju/agents/unit-mysql-router-0/charm/src/mysql_shell/__init__.py", line 74, in _run_code
    self._container.run_mysql_shell(
  File "/var/lib/juju/agents/unit-mysql-router-0/charm/lib/charms/tempo_coordinator_k8s/v0/charm_tracing.py", line 738, in wrapped_function
    return callable(*args, **kwargs)  # type: ignore
  File "/var/lib/juju/agents/unit-mysql-router-0/charm/src/container.py", line 212, in run_mysql_shell
    return self._run_command(args, timeout=timeout, input=input)
  File "/var/lib/juju/agents/unit-mysql-router-0/charm/lib/charms/tempo_coordinator_k8s/v0/charm_tracing.py", line 738, in wrapped_function
    return callable(*args, **kwargs)  # type: ignore
  File "/var/lib/juju/agents/unit-mysql-router-0/charm/src/snap.py", line 272, in _run_command
    raise container.CalledProcessError(
container.CalledProcessError: Command '['charmed-mysql.mysqlsh', '--passwords-from-stdin', '--uri', 'relation-8_7ae48bc246f54a6@:3306', '--python', '--file', '/tmp/mysqlsh_script.py']' returned non-zero exit status 1.
unit-mysql-router-0: 01:49:58 ERROR unit.mysql-router/0.juju-log backend-database:8: Uncaught exception while in charm code:
Traceback (most recent call last):
  File "/var/lib/juju/agents/unit-mysql-router-0/charm/src/snap.py", line 263, in _run_command
    output = subprocess.run(
  File "/usr/lib/python3.10/subprocess.py", line 526, in run
    raise CalledProcessError(retcode, process.args,
subprocess.CalledProcessError: Command '['charmed-mysql.mysqlsh', '--passwords-from-stdin', '--uri', 'relation-8_7ae48bc246f54a6@:3306', '--python', '--file', '/tmp/mysqlsh_script.py']' returned non-zero exit status 1.

During handling of the above exception, another exception occurred:

Traceback (most recent call last):
  File "/var/lib/juju/agents/unit-mysql-router-0/charm/src/charm.py", line 235, in <module>
    ops.main.main(MachineSubordinateRouterCharm)
  File "/var/lib/juju/agents/unit-mysql-router-0/charm/venv/lib/python3.10/site-packages/ops/main.py", line 436, in main
    _emit_charm_event(charm, dispatcher.event_name)
  File "/var/lib/juju/agents/unit-mysql-router-0/charm/venv/lib/python3.10/site-packages/ops/main.py", line 144, in _emit_charm_event
    event_to_emit.emit(*args, **kwargs)
  File "/var/lib/juju/agents/unit-mysql-router-0/charm/venv/lib/python3.10/site-packages/ops/framework.py", line 351, in emit
    framework._emit(event)
  File "/var/lib/juju/agents/unit-mysql-router-0/charm/venv/lib/python3.10/site-packages/ops/framework.py", line 853, in _emit
    self._reemit(event_path)
  File "/var/lib/juju/agents/unit-mysql-router-0/charm/venv/lib/python3.10/site-packages/ops/framework.py", line 942, in _reemit
    custom_handler(event)
  File "/var/lib/juju/agents/unit-mysql-router-0/charm/lib/charms/data_platform_libs/v0/data_interfaces.py", line 3141, in _on_relation_changed_event
    getattr(self.on, "database_created").emit(
  File "/var/lib/juju/agents/unit-mysql-router-0/charm/venv/lib/python3.10/site-packages/ops/framework.py", line 351, in emit
    framework._emit(event)
  File "/var/lib/juju/agents/unit-mysql-router-0/charm/venv/lib/python3.10/site-packages/ops/framework.py", line 853, in _emit
    self._reemit(event_path)
  File "/var/lib/juju/agents/unit-mysql-router-0/charm/venv/lib/python3.10/site-packages/ops/framework.py", line 942, in _reemit
    custom_handler(event)
  File "/var/lib/juju/agents/unit-mysql-router-0/charm/lib/charms/tempo_coordinator_k8s/v0/charm_tracing.py", line 738, in wrapped_function
    return callable(*args, **kwargs)  # type: ignore
  File "/var/lib/juju/agents/unit-mysql-router-0/charm/src/abstract_charm.py", line 344, in reconcile
    self._database_provides.reconcile_users(
  File "/var/lib/juju/agents/unit-mysql-router-0/charm/lib/charms/tempo_coordinator_k8s/v0/charm_tracing.py", line 738, in wrapped_function
    return callable(*args, **kwargs)  # type: ignore
  File "/var/lib/juju/agents/unit-mysql-router-0/charm/src/relations/database_providers_wrapper.py", line 77, in reconcile_users
    self._database_provides.reconcile_users(
  File "/var/lib/juju/agents/unit-mysql-router-0/charm/src/relations/database_provides.py", line 306, in reconcile_users
    relation.create_database_and_user(
  File "/var/lib/juju/agents/unit-mysql-router-0/charm/src/relations/database_provides.py", line 123, in create_database_and_user
    shell.delete_user(username, must_exist=False)
  File "/var/lib/juju/agents/unit-mysql-router-0/charm/src/mysql_shell/__init__.py", line 207, in delete_user
    self._run_sql([statement])
  File "/var/lib/juju/agents/unit-mysql-router-0/charm/src/mysql_shell/__init__.py", line 113, in _run_sql
    self._run_code(
  File "/var/lib/juju/agents/unit-mysql-router-0/charm/src/mysql_shell/__init__.py", line 74, in _run_code
    self._container.run_mysql_shell(
  File "/var/lib/juju/agents/unit-mysql-router-0/charm/lib/charms/tempo_coordinator_k8s/v0/charm_tracing.py", line 738, in wrapped_function
    return callable(*args, **kwargs)  # type: ignore
  File "/var/lib/juju/agents/unit-mysql-router-0/charm/src/container.py", line 212, in run_mysql_shell
    return self._run_command(args, timeout=timeout, input=input)
  File "/var/lib/juju/agents/unit-mysql-router-0/charm/lib/charms/tempo_coordinator_k8s/v0/charm_tracing.py", line 738, in wrapped_function
    return callable(*args, **kwargs)  # type: ignore
  File "/var/lib/juju/agents/unit-mysql-router-0/charm/src/snap.py", line 272, in _run_command
    raise container.CalledProcessError(
container.CalledProcessError: Command '['charmed-mysql.mysqlsh', '--passwords-from-stdin', '--uri', 'relation-8_7ae48bc246f54a6@:3306', '--python', '--file', '/tmp/mysqlsh_script.py']' returned non-zero exit status 1.
unit-mysql-router-3: 01:49:58 ERROR juju.worker.uniter.operation hook "backend-database-relation-changed" (via hook dispatching script: dispatch) failed: exit status 1
unit-mysql-router-2: 01:49:58 ERROR juju.worker.uniter.operation hook "backend-database-relation-changed" (via hook dispatching script: dispatch) failed: exit status 1
unit-mysql-router-0: 01:49:58 ERROR juju.worker.uniter.operation hook "backend-database-relation-changed" (via hook dispatching script: dispatch) failed: exit status 1
unit-hacluster-3: 01:51:01 ERROR juju.worker.meterstatus error running "meter-status-changed": charm missing from disk

[32mINFO    [0m pytest_operator.plugin:plugin.py:947 Forgetting model main...